Workbook
Name BudgetCategory: 'תקציב להבראה'!$G$8:$G$164
Name Category: 'תקציב וביצוע'!$B$2:$B$1028
Name Cols: 'תקציב להבראה'!#REF!
Name CurrDate: חובות!$B$2
Name CurrentIncome: 'תקציב להבראה'!$C$165
Name CurrentMonthlyDebt: 'פריסת חובות'!$C$42
Name CurrentOutgo: 'תקציב להבראה'!$C$139
Name Debts_Debt: OFFSET(חובות!$A$9,1,MATCH("סכום החוב",חובות!$9:$9,0)-1,COUNTA(חובות!$A$9:$A$200)-2)
Name Debts_Int: OFFSET(חובות!$A$9,1,MATCH("אחוז ריבית",חובות!$9:$9,0)-1,COUNTA(חובות!$A$9:$A$200)-2)
Name Debts_Name: OFFSET(חובות!$A$9,1,MATCH("שם הנושה",חובות!$9:$9,0)-1,COUNTA(חובות!$A$9:$A$200)-2)
Name Debts_Pmt: OFFSET(חובות!$A$9,1,MATCH("סכום החזר בחודש הנוכחי",חובות!$9:$9,0)-1,COUNTA(חובות!$A$9:$A$200)-2)
Name Debts_PmtsLeft: OFFSET(חובות!$A$9,1,MATCH("מס' תשלומים נותרים",חובות!$9:$9,0)-1,COUNTA(חובות!$A$9:$A$200)-2)
Name Debts_Yitra: OFFSET(חובות!$A$9,1,MATCH("נותר לתשלום",חובות!$9:$9,0)-1,COUNTA(חובות!$A$9:$A$200)-2)
Name DebtSplit: Par!$B$10:$B$100
Name ExpCol: 'תקציב להבראה'!#REF!
Name ExpFig: 'תקציב להבראה'!#REF!
Name ExpRows: 'תקציב להבראה'!#REF!
Name Family: 'תקציב להבראה'!$C$1
Name ImportExpenseRange: OFFSET(Category,Rows, Cols, ExpRows, ExpCol)
Name ImportExpFigRange: OFFSET(Category,Rows, ExpFig, ExpRows, ExpCol)
Name InCol: 'תקציב להבראה'!#REF!
Name InColOffSet: 'תקציב להבראה'!#REF!
Name IncomeFigRange: OFFSET(Category,InRows,ExpFig, InRow, InCol)
Name IncomeRange: OFFSET(Category,InRows,InColOffSet, InRow, InCol)
Name InRow: 'תקציב להבראה'!#REF!
Name InRows: 'תקציב להבראה'!#REF!
Name LoanOptionNames: 'תכנון הבראה'!$U$6:$U$11
Name LoanOptionNames_NS: 'תכנון הבראה'!$X$6:$X$8
Name LoanOptions: 'תכנון הבראה'!$U$6:$V$11
Name LoanTotal: 'תכנון הבראה'!$B$38
Name PeraonTotal: 'תכנון הבראה'!$G$42
Name PidyonotTotal: 'תכנון הבראה'!#REF!
Name Rows: 'תקציב להבראה'!#REF!

Sheet הסברים
O4: גרסא: | P4: 1.5
B6: סימולטור לתוכנית הבראה
C8: שלבי העבודה | K8: לשאלות, הערות והארות: | P8: ronistaier@paamonim.org
C9: יבוא נתונים מהתוכנה לקובץ זה:
D10: א. יבוא תקציב וביצוע לפי ההוראות בגליון "תקציב וביצוע"
D11: ב. יבוא חובות לפי ההוראות בגליון "חובות"
C12: כעת הקובץ מוכן לתכנון וסימולציה של תכנית ההבראה. שמרו אותו בשם משמעותי (לדוגמא: "תכנית הבראה למשפחת כהן-חלופה1.XLS")
C14: תכנון תקציב/י הבראה בגליון "תקציב להבראה"
D15: א. ברירת המחדל עבור התקציב המוצע הינו התקציב הקיים, אולם ניתן לדרוס את הנוסחא ולרשום כל סכום אחר.
D16: ב. מומלץ להוסיף הערה במקרה שמשנים את התקציב המוצע.
D17: ג. בתחתית הגיליון מופיע סיכום של התקציב. כדאי לשים לב לשורה המציגה את ההפרש כולל החזר חובות.
C19: תכנון ההבראה ע"ב המשאבים הקיימים (חסכונות, קרנות וכו') ומשאבים שניתן להשיג (הלוואות, סיוע מהורים, מענקים וכו') בגליון "תכנון הבראה".
C20: הגיליון מחולק למספר שלבים, אפשר ורצוי לחזור מדי פעם על השלבים על מנת לראות שהתכנית הכוללת סבירה והגיונית.
C22: שלב 1: תכנון תקציב
D23: בשלב זה עליכם להעריך את התקציב הצפוי בעתיד הנראה לעין. ניתן להוסיף עוד שני תקציבים כאשר יש לשים לרישום תקין של מספר החודש שממנו ואילך התקציב נכנס לתוקף. לדוג' אם אתם מעריכים שבעוד שנה מהיום התקציב ישתנה עליכם לרשום תחת "תקציב מוצע 2" את ההכנסות וההוצאות הצפויות ומתחת לשורת ההפרש לרשום 13 (כיוון שהחל מהחודש ה-13 התקציב משתנה)
C24: שלב 2: כספים זמינים (חסכונות, פדיון פיצויים, מענקי הבראה וכו')
D25: בשלב זה עליכם לפרט את כספי החסכון הזמינים למשפחה. ניתן לערוך את הכותרות בהתאם. אם חסרים לכם שורות ניתן לאחד מספר חסכונות תחת שורה אחת. תחת הכותרת "סכום" עליכם לרשום את סה"כ הסכום הקיים, ותחת הכותרת "סכום למשיכה" עליכם לרשום את הסכום שיימשך לצורך מימוש תכנית ההבראה.
C26: שלב 3: הלוואות זמינות
D27: בשלב זה עליכם לפרט את ההלוואות החדשות שאתם ממליצים למשפחה לקחת לצורך מימוש תכנית ההבראה. אפשר ורצוי לערוך את הכותרות. יש לרשום את סך ההלוואה, את הריבית ואת מספר חודשי ההחזר. בהתאם תקבלו את סך ההחזר החודשי.
C28: כעת כדאי לשים לב לבדיקת הביניים לפני שממשיכים.
C29: שלב 4: טיפול בחובות שבהסדר
D30: הנתונים המופיעים בטבלה זו נמשכים מגיליון "חובות - פלט מהמערכת". מטרת הטבלה היא לעזור לכם לקבל החלטות לגבי צורת ודחיפות הטיפול בחובות השונים. הפעולות העומדים לרשותכם הינם להלן:
D31: א. "ללא שינוי"
D32: ב. "פרעון מלא" - החוב יימחק במלואו במיידי. יש לרשום את סכום הפרעון המלא וזאת כיוון שאנו מניחים שעלות הפרעון בפועל שונה מהיתרה המופיעה בדוח.
D33: ג. "הקפאה" - יש לרשום את מספר חודשי ההקפאה. יש לשים לב שאחרי שמסתיימת ההקפאה ההחזר החודשים ממשיך כפי שהוא היום.
D34: ד. "פריסה מחדש" - יש לרשום תחת "תקופה" את מספר חודשי ההחזר החדש. הכלי יחשב עבורכם את ההחזר החודשי החדש על סמך הריבית המקורית מהדוח. אם הריבית בפועל שונה ניתן לשנות זאת ע"י שינוי הנתון בדוח.
D35: ה. "ויתור חלקי" - יש לרשום את את סך הויתור. הכלי יחשב את ההחזר החודשי החדש באופן יחסי להחזר הקיים והיתרה החדשה.
D36: ו. "ויתור מלא" - החוב יימחק במלואו.
C38: שלב 5: טיפול בחובות שלא בהסדר
D39: הנתונים המופיעים בטבלא זו נמשכים מגיליון "חובות - פלט מהמערכת". מטרת הטבלא היא לעזור לכם לקבל החלטות לגבי צורת הטיפול בחובות שנכון להיום אינם בטיפול. שימו לב שברירת המחדל הינה שהחובות לא יטופלו כלל ולכן חשוב לבחור פעולה מתאימה.
D40: א. "ללא שינוי"
D41: ב. "פרעון מלא" - החוב יימחק במלואו במיידי. יש לרשום את סכום הפרעון המלא וזאת כיוון שאנו מניחים שעלות הפרעון בפועל שונה מהיתרה המופיעה בדוח.
D42: ג. "פריסה מחדש" - יש לרשום את מספר חודשי ההחזר וכן את הריבית. הכלי יחשב עבורכם את ההחזר החודשי החדש.
C44: בחינת תכנית ההבראה על ציר הזמן בגליון "סיכום ויזואלי" במידת הצורך יש לחזור לשלבים 2-3 לבחינת שינויים נוספים.
C46: בחינת התנועה הכספית הצפויה בשנים הקרובות בגיליון "סיכום תוצאות". ניתן להציג פירוט רב יותר ע"י לחיצה על ה "+" שבצד.
C47: בגיליון מוצג התזרים כיום, התזרים הצפוי וכן את התפתחות יתרת החובות לאורך זמן.
C53: רשימת תיקונים בין גרסאות
B54: 1.01 | C54: גיליון "סיכום ויזואלי", גרף התפתחות יתרת חובות המשפחה, שונה יתרת חובות שלא בהסדר ליתרת חובות שלא בהסדר לאחר תכנית ההבראה
B55: 1.02 | C55: תיקון באג הלוואות
C56: צביעה בכתום כאשר תקציב מוצע שונה מתקציב קיים
...

Sheet תקציב וביצוע

Sheet חובות

Sheet Par
A1: גיליון עזר לנוסחאות השונות בחוברת
A4: נוסחאות עזר לחלוקת החובות בין כאלה שבהסדר לשאינם
A5: מספר החובות | B5: =COUNTIF(B10:B200,">0") -> 0
A6: מתוכן בהסדר | B6: =COUNTIF(B10:B200,"=1") -> 0
A7: מתוכן לא בהסדר | B7: =+B5-B6 -> 0
A9: קידוד החוב
A10: =IF(B10=0,"",IF(B10=1,"בהסדר","לא בהסדר")) | B10: =IFERROR(IF(AND(INDEX(Debts_Name,ROW()-ROW($A$9))<>"",A9>0),IFERROR(IF(VALUE(INDEX(Debts_Pmt,ROW()-ROW($A$9)))>0,1,2),2),0),0) -> 0
A11: =IF(B11=0,"",IF(B11=1,"בהסדר","לא בהסדר")) | B11: =IFERROR(IF(AND(INDEX(Debts_Name,ROW()-ROW($A$9))<>"",A10>0),IFERROR(IF(VALUE(INDEX(Debts_Pmt,ROW()-ROW($A$9)))>0,1,2),2),0),0) -> 0
A12: =IF(B12=0,"",IF(B12=1,"בהסדר","לא בהסדר")) | B12: =IFERROR(IF(AND(INDEX(Debts_Name,ROW()-ROW($A$9))<>"",A11>0),IFERROR(IF(VALUE(INDEX(Debts_Pmt,ROW()-ROW($A$9)))>0,1,2),2),0),0) -> 0
A13: =IF(B13=0,"",IF(B13=1,"בהסדר","לא בהסדר")) | B13: =IFERROR(IF(AND(INDEX(Debts_Name,ROW()-ROW($A$9))<>"",A12>0),IFERROR(IF(VALUE(INDEX(Debts_Pmt,ROW()-ROW($A$9)))>0,1,2),2),0),0) -> 0
A14: =IF(B14=0,"",IF(B14=1,"בהסדר","לא בהסדר")) | B14: =IFERROR(IF(AND(INDEX(Debts_Name,ROW()-ROW($A$9))<>"",A13>0),IFERROR(IF(VALUE(INDEX(Debts_Pmt,ROW()-ROW($A$9)))>0,1,2),2),0),0) -> 0
A15: =IF(B15=0,"",IF(B15=1,"בהסדר","לא בהסדר")) | B15: =IFERROR(IF(AND(INDEX(Debts_Name,ROW()-ROW($A$9))<>"",A14>0),IFERROR(IF(VALUE(INDEX(Debts_Pmt,ROW()-ROW($A$9)))>0,1,2),2),0),0) -> 0
A16: =IF(B16=0,"",IF(B16=1,"בהסדר","לא בהסדר")) | B16: =IFERROR(IF(AND(INDEX(Debts_Name,ROW()-ROW($A$9))<>"",A15>0),IFERROR(IF(VALUE(INDEX(Debts_Pmt,ROW()-ROW($A$9)))>0,1,2),2),0),0) -> 0
A17: =IF(B17=0,"",IF(B17=1,"בהסדר","לא בהסדר")) | B17: =IFERROR(IF(AND(INDEX(Debts_Name,ROW()-ROW($A$9))<>"",A16>0),IFERROR(IF(VALUE(INDEX(Debts_Pmt,ROW()-ROW($A$9)))>0,1,2),2),0),0) -> 0
A18: =IF(B18=0,"",IF(B18=1,"בהסדר","לא בהסדר")) | B18: =IFERROR(IF(AND(INDEX(Debts_Name,ROW()-ROW($A$9))<>"",A17>0),IFERROR(IF(VALUE(INDEX(Debts_Pmt,ROW()-ROW($A$9)))>0,1,2),2),0),0) -> 0
A19: =IF(B19=0,"",IF(B19=1,"בהסדר","לא בהסדר")) | B19: =IFERROR(IF(AND(INDEX(Debts_Name,ROW()-ROW($A$9))<>"",A18>0),IFERROR(IF(VALUE(INDEX(Debts_Pmt,ROW()-ROW($A$9)))>0,1,2),2),0),0) -> 0
A20: =IF(B20=0,"",IF(B20=1,"בהסדר","לא בהסדר")) | B20: =IFERROR(IF(AND(INDEX(Debts_Name,ROW()-ROW($A$9))<>"",A19>0),IFERROR(IF(VALUE(INDEX(Debts_Pmt,ROW()-ROW($A$9)))>0,1,2),2),0),0) -> 0
A21: =IF(B21=0,"",IF(B21=1,"בהסדר","לא בהסדר")) | B21: =IFERROR(IF(AND(INDEX(Debts_Name,ROW()-ROW($A$9))<>"",A20>0),IFERROR(IF(VALUE(INDEX(Debts_Pmt,ROW()-ROW($A$9)))>0,1,2),2),0),0) -> 0
... A100: =IF(B100=0,"",IF(B100=1,"בהסדר","לא בהסדר")) | B100: =IFERROR(IF(AND(INDEX(Debts_Name,ROW()-ROW($A$9))<>"",A99>0),IFERROR(IF(VALUE(INDEX(Debts_Pmt,ROW()-ROW($A$9)))>0,1,2),2),0),0) -> 0
B101: =IFERROR(IF(AND(INDEX(Debts_Name,ROW()-ROW($A$9))<>"",A100>0),IFERROR(IF(VALUE(INDEX(Debts_Pmt,ROW()-ROW($A$9)))>0,1,2),2),0),0) -> 0
B102: =IFERROR(IF(AND(INDEX(Debts_Name,ROW()-ROW($A$9))<>"",A101>0),IFERROR(IF(VALUE(INDEX(Debts_Pmt,ROW()-ROW($A$9)))>0,1,2),2),0),0) -> 0
B103: =IFERROR(IF(AND(INDEX(Debts_Name,ROW()-ROW($A$9))<>"",A102>0),IFERROR(IF(VALUE(INDEX(Debts_Pmt,ROW()-ROW($A$9)))>0,1,2),2),0),0) -> 0
B104: =IFERROR(IF(AND(INDEX(Debts_Name,ROW()-ROW($A$9))<>"",A103>0),IFERROR(IF(VALUE(INDEX(Debts_Pmt,ROW()-ROW($A$9)))>0,1,2),2),0),0) -> 0
B105: =IFERROR(IF(AND(INDEX(Debts_Name,ROW()-ROW($A$9))<>"",A104>0),IFERROR(IF(VALUE(INDEX(Debts_Pmt,ROW()-ROW($A$9)))>0,1,2),2),0),0) -> 0
B106: =IFERROR(IF(AND(INDEX(Debts_Name,ROW()-ROW($A$9))<>"",A105>0),IFERROR(IF(VALUE(INDEX(Debts_Pmt,ROW()-ROW($A$9)))>0,1,2),2),0),0) -> 0
B107: =IFERROR(IF(AND(INDEX(Debts_Name,ROW()-ROW($A$9))<>"",A106>0),IFERROR(IF(VALUE(INDEX(Debts_Pmt,ROW()-ROW($A$9)))>0,1,2),2),0),0) -> 0
B108: =IFERROR(IF(AND(INDEX(Debts_Name,ROW()-ROW($A$9))<>"",A107>0),IFERROR(IF(VALUE(INDEX(Debts_Pmt,ROW()-ROW($A$9)))>0,1,2),2),0),0) -> 0
B109: =IFERROR(IF(AND(INDEX(Debts_Name,ROW()-ROW($A$9))<>"",A108>0),IFERROR(IF(VALUE(INDEX(Debts_Pmt,ROW()-ROW($A$9)))>0,1,2),2),0),0) -> 0
B110: =IFERROR(IF(AND(INDEX(Debts_Name,ROW()-ROW($A$9))<>"",A109>0),IFERROR(IF(VALUE(INDEX(Debts_Pmt,ROW()-ROW($A$9)))>0,1,2),2),0),0) -> 0
B111: =IFERROR(IF(AND(INDEX(Debts_Name,ROW()-ROW($A$9))<>"",A110>0),IFERROR(IF(VALUE(INDEX(Debts_Pmt,ROW()-ROW($A$9)))>0,1,2),2),0),0) -> 0
B112: =IFERROR(IF(AND(INDEX(Debts_Name,ROW()-ROW($A$9))<>"",A111>0),IFERROR(IF(VALUE(INDEX(Debts_Pmt,ROW()-ROW($A$9)))>0,1,2),2),0),0) -> 0
... B200: =IFERROR(IF(AND(INDEX(Debts_Name,ROW()-ROW($A$9))<>"",A199>0),IFERROR(IF(VALUE(INDEX(Debts_Pmt,ROW()-ROW($A$9)))>0,1,2),2),0),0) -> 0

Sheet פריסת חובות
A1: טבלת פריסת חובות
A2: חובות שבהסדר בלבד
A3: משפחת | B3: =חובות!B3 -> 0
A7: =Par!B6 -> 0 | C7: מצב 0 | E7: תשלום ראשון הבא
B8: יתרה | C8: =CurrDate -> 0 | D8: ריבית | E8: =DATE(YEAR(C8),MONTH(C8)+1,1) -> 32 | F8: =DATE(YEAR(E8),MONTH(E8)+1,1) -> 61 | G8: =DATE(YEAR(F8),MONTH(F8)+1,1) -> 92 | H8: =DATE(YEAR(G8),MONTH(G8)+1,1) -> 122 | I8: =DATE(YEAR(H8),MONTH(H8)+1,1) -> 153 | J8: =DATE(YEAR(I8),MONTH(I8)+1,1) -> 183 | K8: =DATE(YEAR(J8),MONTH(J8)+1,1) -> 214 | L8: =DATE(YEAR(K8),MONTH(K8)+1,1) -> 245 | M8: =DATE(YEAR(L8),MONTH(L8)+1,1) -> 275 | ... CZ8: =DATE(YEAR(CY8),MONTH(CY8)+1,1) -> 3044
A9: {=IF(ROWS(A$8:A8)>$A$7,"",INDEX(Debts_Name,SMALL(IF(DebtSplit=1,ROW(Debts_Name)-ROW(חובות!$B$10)+1),ROWS(A$8:A8))))} | B9: {=IFERROR(IF(ROWS(A$8:A8)>$A$7,0,INDEX(Debts_Yitra,SMALL(IF(DebtSplit=1,ROW(Debts_Yitra)-ROW(חובות!$I$10)+1),ROWS(A$8:A8))))*1,0)} -> 0 | C9: {=IFERROR(IF(ROWS(A$8:A8)>$A$7,0,INDEX(Debts_Pmt,SMALL(IF(DebtSplit=1,ROW(Debts_Pmt)-ROW(חובות!$H$10)+1),ROWS(A$8:A8))))*1,0)} -> 0 | D9: {=IFERROR(IF(ROWS(B$8:B8)>$A$7,0,INDEX(Debts_Int,SMALL(IF(DebtSplit=1,ROW(Debts_Int)-ROW(חובות!$F$10)+1),ROWS(B$8:B8))))*1,0)} -> 0 | E9: =C9 -> 0 | F9: =IF($B9="","",MIN($B9-SUM(E9:$E9),$C9)) -> 0 | G9: =IF($B9="","",MIN($B9-SUM($E9:F9),$C9)) -> 0 | H9: =IF($B9="","",MIN($B9-SUM($E9:G9),$C9)) -> 0 | I9: =IF($B9="","",MIN($B9-SUM($E9:H9),$C9)) -> 0 | J9: =IF($B9="","",MIN($B9-SUM($E9:I9),$C9)) -> 0 | K9: =IF($B9="","",MIN($B9-SUM($E9:J9),$C9)) -> 0 | L9: =IF($B9="","",MIN($B9-SUM($E9:K9),$C9)) -> 0 | M9: =IF($B9="","",MIN($B9-SUM($E9:L9),$C9)) -> 0 | N9: =IF($B9="","",MIN($B9-SUM($E9:M9),$C9)) -> 0 | ... CZ9: =IF($B9="","",MIN($B9-SUM($E9:CY9),$C9)) -> 0
A10: {=IF(ROWS(A$8:A9)>$A$7,"",INDEX(Debts_Name,SMALL(IF(DebtSplit=1,ROW(Debts_Name)-ROW(חובות!$B$10)+1),ROWS(A$8:A9))))} | B10: {=IFERROR(IF(ROWS(A$8:A9)>$A$7,0,INDEX(Debts_Yitra,SMALL(IF(DebtSplit=1,ROW(Debts_Yitra)-ROW(חובות!$I$10)+1),ROWS(A$8:A9))))*1,0)} -> 0 | C10: {=IFERROR(IF(ROWS(A$8:A9)>$A$7,0,INDEX(Debts_Pmt,SMALL(IF(DebtSplit=1,ROW(Debts_Pmt)-ROW(חובות!$H$10)+1),ROWS(A$8:A9))))*1,0)} -> 0 | D10: {=IFERROR(IF(ROWS(B$8:B9)>$A$7,0,INDEX(Debts_Int,SMALL(IF(DebtSplit=1,ROW(Debts_Int)-ROW(חובות!$F$10)+1),ROWS(B$8:B9))))*1,0)} -> 0 | E10: =C10 -> 0 | F10: =IF($B10="","",MIN($B10-SUM(E10:$E10),$C10)) -> 0 | G10: =IF($B10="","",MIN($B10-SUM($E10:F10),$C10)) -> 0 | H10: =IF($B10="","",MIN($B10-SUM($E10:G10),$C10)) -> 0 | I10: =IF($B10="","",MIN($B10-SUM($E10:H10),$C10)) -> 0 | J10: =IF($B10="","",MIN($B10-SUM($E10:I10),$C10)) -> 0 | K10: =IF($B10="","",MIN($B10-SUM($E10:J10),$C10)) -> 0 | L10: =IF($B10="","",MIN($B10-SUM($E10:K10),$C10)) -> 0 | M10: =IF($B10="","",MIN($B10-SUM($E10:L10),$C10)) -> 0 | N10: =IF($B10="","",MIN($B10-SUM($E10:M10),$C10)) -> 0 | ... CZ10: =IF($B10="","",MIN($B10-SUM($E10:CY10),$C10)) -> 0
A11: {=IF(ROWS(A$8:A10)>$A$7,"",INDEX(Debts_Name,SMALL(IF(DebtSplit=1,ROW(Debts_Name)-ROW(חובות!$B$10)+1),ROWS(A$8:A10))))} | B11: {=IFERROR(IF(ROWS(A$8:A10)>$A$7,0,INDEX(Debts_Yitra,SMALL(IF(DebtSplit=1,ROW(Debts_Yitra)-ROW(חובות!$I$10)+1),ROWS(A$8:A10))))*1,0)} -> 0 | C11: {=IFERROR(IF(ROWS(A$8:A10)>$A$7,0,INDEX(Debts_Pmt,SMALL(IF(DebtSplit=1,ROW(Debts_Pmt)-ROW(חובות!$H$10)+1),ROWS(A$8:A10))))*1,0)} -> 0 | D11: {=IFERROR(IF(ROWS(B$8:B10)>$A$7,0,INDEX(Debts_Int,SMALL(IF(DebtSplit=1,ROW(Debts_Int)-ROW(חובות!$F$10)+1),ROWS(B$8:B10))))*1,0)} -> 0 | E11: =C11 -> 0 | F11: =IF($B11="","",MIN($B11-SUM(E11:$E11),$C11)) -> 0 | G11: =IF($B11="","",MIN($B11-SUM($E11:F11),$C11)) -> 0 | H11: =IF($B11="","",MIN($B11-SUM($E11:G11),$C11)) -> 0 | I11: =IF($B11="","",MIN($B11-SUM($E11:H11),$C11)) -> 0 | J11: =IF($B11="","",MIN($B11-SUM($E11:I11),$C11)) -> 0 | K11: =IF($B11="","",MIN($B11-SUM($E11:J11),$C11)) -> 0 | L11: =IF($B11="","",MIN($B11-SUM($E11:K11),$C11)) -> 0 | M11: =IF($B11="","",MIN($B11-SUM($E11:L11),$C11)) -> 0 | N11: =IF($B11="","",MIN($B11-SUM($E11:M11),$C11)) -> 0 | ... CZ11: =IF($B11="","",MIN($B11-SUM($E11:CY11),$C11)) -> 0
A12: {=IF(ROWS(A$8:A11)>$A$7,"",INDEX(Debts_Name,SMALL(IF(DebtSplit=1,ROW(Debts_Name)-ROW(חובות!$B$10)+1),ROWS(A$8:A11))))} | B12: {=IFERROR(IF(ROWS(A$8:A11)>$A$7,0,INDEX(Debts_Yitra,SMALL(IF(DebtSplit=1,ROW(Debts_Yitra)-ROW(חובות!$I$10)+1),ROWS(A$8:A11))))*1,0)} -> 0 | C12: {=IFERROR(IF(ROWS(A$8:A11)>$A$7,0,INDEX(Debts_Pmt,SMALL(IF(DebtSplit=1,ROW(Debts_Pmt)-ROW(חובות!$H$10)+1),ROWS(A$8:A11))))*1,0)} -> 0 | D12: {=IFERROR(IF(ROWS(B$8:B11)>$A$7,0,INDEX(Debts_Int,SMALL(IF(DebtSplit=1,ROW(Debts_Int)-ROW(חובות!$F$10)+1),ROWS(B$8:B11))))*1,0)} -> 0 | E12: =C12 -> 0 | F12: =IF($B12="","",MIN($B12-SUM(E12:$E12),$C12)) -> 0 | G12: =IF($B12="","",MIN($B12-SUM($E12:F12),$C12)) -> 0 | H12: =IF($B12="","",MIN($B12-SUM($E12:G12),$C12)) -> 0 | I12: =IF($B12="","",MIN($B12-SUM($E12:H12),$C12)) -> 0 | J12: =IF($B12="","",MIN($B12-SUM($E12:I12),$C12)) -> 0 | K12: =IF($B12="","",MIN($B12-SUM($E12:J12),$C12)) -> 0 | L12: =IF($B12="","",MIN($B12-SUM($E12:K12),$C12)) -> 0 | M12: =IF($B12="","",MIN($B12-SUM($E12:L12),$C12)) -> 0 | N12: =IF($B12="","",MIN($B12-SUM($E12:M12),$C12)) -> 0 | ... CZ12: =IF($B12="","",MIN($B12-SUM($E12:CY12),$C12)) -> 0
A13: {=IF(ROWS(A$8:A12)>$A$7,"",INDEX(Debts_Name,SMALL(IF(DebtSplit=1,ROW(Debts_Name)-ROW(חובות!$B$10)+1),ROWS(A$8:A12))))} | B13: {=IFERROR(IF(ROWS(A$8:A12)>$A$7,0,INDEX(Debts_Yitra,SMALL(IF(DebtSplit=1,ROW(Debts_Yitra)-ROW(חובות!$I$10)+1),ROWS(A$8:A12))))*1,0)} -> 0 | C13: {=IFERROR(IF(ROWS(A$8:A12)>$A$7,0,INDEX(Debts_Pmt,SMALL(IF(DebtSplit=1,ROW(Debts_Pmt)-ROW(חובות!$H$10)+1),ROWS(A$8:A12))))*1,0)} -> 0 | D13: {=IFERROR(IF(ROWS(B$8:B12)>$A$7,0,INDEX(Debts_Int,SMALL(IF(DebtSplit=1,ROW(Debts_Int)-ROW(חובות!$F$10)+1),ROWS(B$8:B12))))*1,0)} -> 0 | E13: =C13 -> 0 | F13: =IF($B13="","",MIN($B13-SUM(E13:$E13),$C13)) -> 0 | G13: =IF($B13="","",MIN($B13-SUM($E13:F13),$C13)) -> 0 | H13: =IF($B13="","",MIN($B13-SUM($E13:G13),$C13)) -> 0 | I13: =IF($B13="","",MIN($B13-SUM($E13:H13),$C13)) -> 0 | J13: =IF($B13="","",MIN($B13-SUM($E13:I13),$C13)) -> 0 | K13: =IF($B13="","",MIN($B13-SUM($E13:J13),$C13)) -> 0 | L13: =IF($B13="","",MIN($B13-SUM($E13:K13),$C13)) -> 0 | M13: =IF($B13="","",MIN($B13-SUM($E13:L13),$C13)) -> 0 | N13: =IF($B13="","",MIN($B13-SUM($E13:M13),$C13)) -> 0 | ... CZ13: =IF($B13="","",MIN($B13-SUM($E13:CY13),$C13)) -> 0
A14: {=IF(ROWS(A$8:A13)>$A$7,"",INDEX(Debts_Name,SMALL(IF(DebtSplit=1,ROW(Debts_Name)-ROW(חובות!$B$10)+1),ROWS(A$8:A13))))} | B14: {=IFERROR(IF(ROWS(A$8:A13)>$A$7,0,INDEX(Debts_Yitra,SMALL(IF(DebtSplit=1,ROW(Debts_Yitra)-ROW(חובות!$I$10)+1),ROWS(A$8:A13))))*1,0)} -> 0 | C14: {=IFERROR(IF(ROWS(A$8:A13)>$A$7,0,INDEX(Debts_Pmt,SMALL(IF(DebtSplit=1,ROW(Debts_Pmt)-ROW(חובות!$H$10)+1),ROWS(A$8:A13))))*1,0)} -> 0 | D14: {=IFERROR(IF(ROWS(B$8:B13)>$A$7,0,INDEX(Debts_Int,SMALL(IF(DebtSplit=1,ROW(Debts_Int)-ROW(חובות!$F$10)+1),ROWS(B$8:B13))))*1,0)} -> 0 | E14: =C14 -> 0 | F14: =IF($B14="","",MIN($B14-SUM(E14:$E14),$C14)) -> 0 | G14: =IF($B14="","",MIN($B14-SUM($E14:F14),$C14)) -> 0 | H14: =IF($B14="","",MIN($B14-SUM($E14:G14),$C14)) -> 0 | I14: =IF($B14="","",MIN($B14-SUM($E14:H14),$C14)) -> 0 | J14: =IF($B14="","",MIN($B14-SUM($E14:I14),$C14)) -> 0 | K14: =IF($B14="","",MIN($B14-SUM($E14:J14),$C14)) -> 0 | L14: =IF($B14="","",MIN($B14-SUM($E14:K14),$C14)) -> 0 | M14: =IF($B14="","",MIN($B14-SUM($E14:L14),$C14)) -> 0 | N14: =IF($B14="","",MIN($B14-SUM($E14:M14),$C14)) -> 0 | ... CZ14: =IF($B14="","",MIN($B14-SUM($E14:CY14),$C14)) -> 0
A15: {=IF(ROWS(A$8:A14)>$A$7,"",INDEX(Debts_Name,SMALL(IF(DebtSplit=1,ROW(Debts_Name)-ROW(חובות!$B$10)+1),ROWS(A$8:A14))))} | B15: {=IFERROR(IF(ROWS(A$8:A14)>$A$7,0,INDEX(Debts_Yitra,SMALL(IF(DebtSplit=1,ROW(Debts_Yitra)-ROW(חובות!$I$10)+1),ROWS(A$8:A14))))*1,0)} -> 0 | C15: {=IFERROR(IF(ROWS(A$8:A14)>$A$7,0,INDEX(Debts_Pmt,SMALL(IF(DebtSplit=1,ROW(Debts_Pmt)-ROW(חובות!$H$10)+1),ROWS(A$8:A14))))*1,0)} -> 0 | D15: {=IFERROR(IF(ROWS(B$8:B14)>$A$7,0,INDEX(Debts_Int,SMALL(IF(DebtSplit=1,ROW(Debts_Int)-ROW(חובות!$F$10)+1),ROWS(B$8:B14))))*1,0)} -> 0 | E15: =C15 -> 0 | F15: =IF($B15="","",MIN($B15-SUM(E15:$E15),$C15)) -> 0 | G15: =IF($B15="","",MIN($B15-SUM($E15:F15),$C15)) -> 0 | H15: =IF($B15="","",MIN($B15-SUM($E15:G15),$C15)) -> 0 | I15: =IF($B15="","",MIN($B15-SUM($E15:H15),$C15)) -> 0 | J15: =IF($B15="","",MIN($B15-SUM($E15:I15),$C15)) -> 0 | K15: =IF($B15="","",MIN($B15-SUM($E15:J15),$C15)) -> 0 | L15: =IF($B15="","",MIN($B15-SUM($E15:K15),$C15)) -> 0 | M15: =IF($B15="","",MIN($B15-SUM($E15:L15),$C15)) -> 0 | N15: =IF($B15="","",MIN($B15-SUM($E15:M15),$C15)) -> 0 | ... CZ15: =IF($B15="","",MIN($B15-SUM($E15:CY15),$C15)) -> 0
A16: {=IF(ROWS(A$8:A15)>$A$7,"",INDEX(Debts_Name,SMALL(IF(DebtSplit=1,ROW(Debts_Name)-ROW(חובות!$B$10)+1),ROWS(A$8:A15))))} | B16: {=IFERROR(IF(ROWS(A$8:A15)>$A$7,0,INDEX(Debts_Yitra,SMALL(IF(DebtSplit=1,ROW(Debts_Yitra)-ROW(חובות!$I$10)+1),ROWS(A$8:A15))))*1,0)} -> 0 | C16: {=IFERROR(IF(ROWS(A$8:A15)>$A$7,0,INDEX(Debts_Pmt,SMALL(IF(DebtSplit=1,ROW(Debts_Pmt)-ROW(חובות!$H$10)+1),ROWS(A$8:A15))))*1,0)} -> 0 | D16: {=IFERROR(IF(ROWS(B$8:B15)>$A$7,0,INDEX(Debts_Int,SMALL(IF(DebtSplit=1,ROW(Debts_Int)-ROW(חובות!$F$10)+1),ROWS(B$8:B15))))*1,0)} -> 0 | E16: =C16 -> 0 | F16: =IF($B16="","",MIN($B16-SUM(E16:$E16),$C16)) -> 0 | G16: =IF($B16="","",MIN($B16-SUM($E16:F16),$C16)) -> 0 | H16: =IF($B16="","",MIN($B16-SUM($E16:G16),$C16)) -> 0 | I16: =IF($B16="","",MIN($B16-SUM($E16:H16),$C16)) -> 0 | J16: =IF($B16="","",MIN($B16-SUM($E16:I16),$C16)) -> 0 | K16: =IF($B16="","",MIN($B16-SUM($E16:J16),$C16)) -> 0 | L16: =IF($B16="","",MIN($B16-SUM($E16:K16),$C16)) -> 0 | M16: =IF($B16="","",MIN($B16-SUM($E16:L16),$C16)) -> 0 | N16: =IF($B16="","",MIN($B16-SUM($E16:M16),$C16)) -> 0 | ... CZ16: =IF($B16="","",MIN($B16-SUM($E16:CY16),$C16)) -> 0
A17: {=IF(ROWS(A$8:A16)>$A$7,"",INDEX(Debts_Name,SMALL(IF(DebtSplit=1,ROW(Debts_Name)-ROW(חובות!$B$10)+1),ROWS(A$8:A16))))} | B17: {=IFERROR(IF(ROWS(A$8:A16)>$A$7,0,INDEX(Debts_Yitra,SMALL(IF(DebtSplit=1,ROW(Debts_Yitra)-ROW(חובות!$I$10)+1),ROWS(A$8:A16))))*1,0)} -> 0 | C17: {=IFERROR(IF(ROWS(A$8:A16)>$A$7,0,INDEX(Debts_Pmt,SMALL(IF(DebtSplit=1,ROW(Debts_Pmt)-ROW(חובות!$H$10)+1),ROWS(A$8:A16))))*1,0)} -> 0 | D17: {=IFERROR(IF(ROWS(B$8:B16)>$A$7,0,INDEX(Debts_Int,SMALL(IF(DebtSplit=1,ROW(Debts_Int)-ROW(חובות!$F$10)+1),ROWS(B$8:B16))))*1,0)} -> 0 | E17: =C17 -> 0 | F17: =IF($B17="","",MIN($B17-SUM(E17:$E17),$C17)) -> 0 | G17: =IF($B17="","",MIN($B17-SUM($E17:F17),$C17)) -> 0 | H17: =IF($B17="","",MIN($B17-SUM($E17:G17),$C17)) -> 0 | I17: =IF($B17="","",MIN($B17-SUM($E17:H17),$C17)) -> 0 | J17: =IF($B17="","",MIN($B17-SUM($E17:I17),$C17)) -> 0 | K17: =IF($B17="","",MIN($B17-SUM($E17:J17),$C17)) -> 0 | L17: =IF($B17="","",MIN($B17-SUM($E17:K17),$C17)) -> 0 | M17: =IF($B17="","",MIN($B17-SUM($E17:L17),$C17)) -> 0 | N17: =IF($B17="","",MIN($B17-SUM($E17:M17),$C17)) -> 0 | ... CZ17: =IF($B17="","",MIN($B17-SUM($E17:CY17),$C17)) -> 0
A18: {=IF(ROWS(A$8:A17)>$A$7,"",INDEX(Debts_Name,SMALL(IF(DebtSplit=1,ROW(Debts_Name)-ROW(חובות!$B$10)+1),ROWS(A$8:A17))))} | B18: {=IFERROR(IF(ROWS(A$8:A17)>$A$7,0,INDEX(Debts_Yitra,SMALL(IF(DebtSplit=1,ROW(Debts_Yitra)-ROW(חובות!$I$10)+1),ROWS(A$8:A17))))*1,0)} -> 0 | C18: {=IFERROR(IF(ROWS(A$8:A17)>$A$7,0,INDEX(Debts_Pmt,SMALL(IF(DebtSplit=1,ROW(Debts_Pmt)-ROW(חובות!$H$10)+1),ROWS(A$8:A17))))*1,0)} -> 0 | D18: {=IFERROR(IF(ROWS(B$8:B17)>$A$7,0,INDEX(Debts_Int,SMALL(IF(DebtSplit=1,ROW(Debts_Int)-ROW(חובות!$F$10)+1),ROWS(B$8:B17))))*1,0)} -> 0 | E18: =C18 -> 0 | F18: =IF($B18="","",MIN($B18-SUM(E18:$E18),$C18)) -> 0 | G18: =IF($B18="","",MIN($B18-SUM($E18:F18),$C18)) -> 0 | H18: =IF($B18="","",MIN($B18-SUM($E18:G18),$C18)) -> 0 | I18: =IF($B18="","",MIN($B18-SUM($E18:H18),$C18)) -> 0 | J18: =IF($B18="","",MIN($B18-SUM($E18:I18),$C18)) -> 0 | K18: =IF($B18="","",MIN($B18-SUM($E18:J18),$C18)) -> 0 | L18: =IF($B18="","",MIN($B18-SUM($E18:K18),$C18)) -> 0 | M18: =IF($B18="","",MIN($B18-SUM($E18:L18),$C18)) -> 0 | N18: =IF($B18="","",MIN($B18-SUM($E18:M18),$C18)) -> 0 | ... CZ18: =IF($B18="","",MIN($B18-SUM($E18:CY18),$C18)) -> 0
A19: {=IF(ROWS(A$8:A18)>$A$7,"",INDEX(Debts_Name,SMALL(IF(DebtSplit=1,ROW(Debts_Name)-ROW(חובות!$B$10)+1),ROWS(A$8:A18))))} | B19: {=IFERROR(IF(ROWS(A$8:A18)>$A$7,0,INDEX(Debts_Yitra,SMALL(IF(DebtSplit=1,ROW(Debts_Yitra)-ROW(חובות!$I$10)+1),ROWS(A$8:A18))))*1,0)} -> 0 | C19: {=IFERROR(IF(ROWS(A$8:A18)>$A$7,0,INDEX(Debts_Pmt,SMALL(IF(DebtSplit=1,ROW(Debts_Pmt)-ROW(חובות!$H$10)+1),ROWS(A$8:A18))))*1,0)} -> 0 | D19: {=IFERROR(IF(ROWS(B$8:B18)>$A$7,0,INDEX(Debts_Int,SMALL(IF(DebtSplit=1,ROW(Debts_Int)-ROW(חובות!$F$10)+1),ROWS(B$8:B18))))*1,0)} -> 0 | E19: =C19 -> 0 | F19: =IF($B19="","",MIN($B19-SUM(E19:$E19),$C19)) -> 0 | G19: =IF($B19="","",MIN($B19-SUM($E19:F19),$C19)) -> 0 | H19: =IF($B19="","",MIN($B19-SUM($E19:G19),$C19)) -> 0 | I19: =IF($B19="","",MIN($B19-SUM($E19:H19),$C19)) -> 0 | J19: =IF($B19="","",MIN($B19-SUM($E19:I19),$C19)) -> 0 | K19: =IF($B19="","",MIN($B19-SUM($E19:J19),$C19)) -> 0 | L19: =IF($B19="","",MIN($B19-SUM($E19:K19),$C19)) -> 0 | M19: =IF($B19="","",MIN($B19-SUM($E19:L19),$C19)) -> 0 | N19: =IF($B19="","",MIN($B19-SUM($E19:M19),$C19)) -> 0 | ... CZ19: =IF($B19="","",MIN($B19-SUM($E19:CY19),$C19)) -> 0
A20: {=IF(ROWS(A$8:A19)>$A$7,"",INDEX(Debts_Name,SMALL(IF(DebtSplit=1,ROW(Debts_Name)-ROW(חובות!$B$10)+1),ROWS(A$8:A19))))} | B20: {=IFERROR(IF(ROWS(A$8:A19)>$A$7,0,INDEX(Debts_Yitra,SMALL(IF(DebtSplit=1,ROW(Debts_Yitra)-ROW(חובות!$I$10)+1),ROWS(A$8:A19))))*1,0)} -> 0 | C20: {=IFERROR(IF(ROWS(A$8:A19)>$A$7,0,INDEX(Debts_Pmt,SMALL(IF(DebtSplit=1,ROW(Debts_Pmt)-ROW(חובות!$H$10)+1),ROWS(A$8:A19))))*1,0)} -> 0 | D20: {=IFERROR(IF(ROWS(B$8:B19)>$A$7,0,INDEX(Debts_Int,SMALL(IF(DebtSplit=1,ROW(Debts_Int)-ROW(חובות!$F$10)+1),ROWS(B$8:B19))))*1,0)} -> 0 | E20: =C20 -> 0 | F20: =IF($B20="","",MIN($B20-SUM(E20:$E20),$C20)) -> 0 | G20: =IF($B20="","",MIN($B20-SUM($E20:F20),$C20)) -> 0 | H20: =IF($B20="","",MIN($B20-SUM($E20:G20),$C20)) -> 0 | I20: =IF($B20="","",MIN($B20-SUM($E20:H20),$C20)) -> 0 | J20: =IF($B20="","",MIN($B20-SUM($E20:I20),$C20)) -> 0 | K20: =IF($B20="","",MIN($B20-SUM($E20:J20),$C20)) -> 0 | L20: =IF($B20="","",MIN($B20-SUM($E20:K20),$C20)) -> 0 | M20: =IF($B20="","",MIN($B20-SUM($E20:L20),$C20)) -> 0 | N20: =IF($B20="","",MIN($B20-SUM($E20:M20),$C20)) -> 0 | ... CZ20: =IF($B20="","",MIN($B20-SUM($E20:CY20),$C20)) -> 0
... A41: {=IF(ROWS(A$8:A40)>$A$7,"",INDEX(Debts_Name,SMALL(IF(DebtSplit=1,ROW(Debts_Name)-ROW(חובות!$B$10)+1),ROWS(A$8:A40))))} | B41: {=IFERROR(IF(ROWS(A$8:A40)>$A$7,0,INDEX(Debts_Yitra,SMALL(IF(DebtSplit=1,ROW(Debts_Yitra)-ROW(חובות!$I$10)+1),ROWS(A$8:A40))))*1,0)} -> 0 | C41: {=IFERROR(IF(ROWS(A$8:A40)>$A$7,0,INDEX(Debts_Pmt,SMALL(IF(DebtSplit=1,ROW(Debts_Pmt)-ROW(חובות!$H$10)+1),ROWS(A$8:A40))))*1,0)} -> 0 | D41: {=IFERROR(IF(ROWS(B$8:B40)>$A$7,0,INDEX(Debts_Int,SMALL(IF(DebtSplit=1,ROW(Debts_Int)-ROW(חובות!$F$10)+1),ROWS(B$8:B40))))*1,0)} -> 0 | E41: =C41 -> 0 | F41: =IF($B41="","",MIN($B41-SUM(E41:$E41),$C41)) -> 0 | G41: =IF($B41="","",MIN($B41-SUM($E41:F41),$C41)) -> 0 | H41: =IF($B41="","",MIN($B41-SUM($E41:G41),$C41)) -> 0 | I41: =IF($B41="","",MIN($B41-SUM($E41:H41),$C41)) -> 0 | J41: =IF($B41="","",MIN($B41-SUM($E41:I41),$C41)) -> 0 | K41: =IF($B41="","",MIN($B41-SUM($E41:J41),$C41)) -> 0 | L41: =IF($B41="","",MIN($B41-SUM($E41:K41),$C41)) -> 0 | M41: =IF($B41="","",MIN($B41-SUM($E41:L41),$C41)) -> 0 | N41: =IF($B41="","",MIN($B41-SUM($E41:M41),$C41)) -> 0 | ... CZ41: =IF($B41="","",MIN($B41-SUM($E41:CY41),$C41)) -> 0
A42: סה"כ: | B42: =SUM(B9:B41) -> 0 | C42: =SUM(C9:C41) -> 0 | E42: =SUM(E9:E41) -> 0 | F42: =SUM(F9:F41) -> 0 | G42: =SUM(G9:G41) -> 0 | H42: =SUM(H9:H41) -> 0 | I42: =SUM(I9:I41) -> 0 | J42: =SUM(J9:J41) -> 0 | K42: =SUM(K9:K41) -> 0 | L42: =SUM(L9:L41) -> 0 | ... CZ42: =SUM(CZ9:CZ41) -> 0

Sheet תקציב להבראה
B1: תקציב הבראה למשפחת | C1: =חובות!B3 -> 0
B2: תקציב | C2: נוכחי | D2: מוצע | E2: הערות
B3: הוצאות | C3: =SUM(C8:C138) -> #N/A | D3: =SUM(D8:D138) -> #N/A | G3: שורה שבה נמצאת המילה "הכנסות" | H3: =MATCH("הכנסות",'תקציב וביצוע'!A1:A500,0) -> #N/A
B4: הכנסות | C4: =CurrentIncome -> #N/A | D4: =D165 -> #N/A | G4: שורה שבה מופיעה המילה התחייבויות לראשונה | H4: =MATCH("התחייבויות",'תקציב וביצוע'!A2:A500,0) -> #N/A
B5: הפרש | C5: =C4-C3 -> #N/A | D5: =D4-D3 -> #N/A | G5: מרווח בין התחייבויות לנכסים | H5: =MATCH("נכסים",'תקציב וביצוע'!A2:A500,0)-H4 -> #N/A
B6: החזרי חובות | C6: =C168 -> #N/A | D6: =C6 -> #N/A | G6: שורה שבה נמצאת המילה "סה"כ" פעם שניה | H6: =MATCH("סה""כ",OFFSET('תקציב וביצוע'!A1:A500,H3,0),FALSE) -> #N/A
B7: הפרש כולל החזרי חובות | C7: =C5-C6 -> #N/A | D7: =D5-D6 -> #N/A
B8: =IF(ROW(E8)<$H$3-$H$5-11,OFFSET(G8,IF(ROW(E8)>=$H$4-5,$H$5-2,0),0),0) -> #N/A | C8: =VLOOKUP(B8,$G$8:$I$138,3,FALSE) -> #N/A | D8: =C8 -> #N/A | G8: =OFFSET(J8,K8,0) -> 0 | I8: =IFERROR(VLOOKUP(G8,'תקציב וביצוע'!$A$1:$L$200,2,FALSE),0) -> 0 | J8: ='תקציב וביצוע'!A2 -> 0 | K8: =IF(NOT(ISERROR(MATCH(OFFSET(J8,K7,0),$M$8:$M$26,0))),K7+1,K7) -> 0 | M8: מזון ופארמה
B9: =IF(ROW(E9)<$H$3-$H$5-11,OFFSET(G9,IF(ROW(E9)>=$H$4-5,$H$5-2,0),0),0) -> #N/A | C9: =VLOOKUP(B9,$G$8:$I$138,3,FALSE) -> #N/A | D9: =C9 -> #N/A | G9: =OFFSET(J9,K9,0) -> 0 | I9: =IFERROR(VLOOKUP(G9,'תקציב וביצוע'!$A$1:$L$200,2,FALSE),0) -> 0 | J9: ='תקציב וביצוע'!A3 -> 0 | K9: =IF(NOT(ISERROR(MATCH(OFFSET(J9,K8,0),$M$8:$M$26,0))),K8+1,K8) -> 0 | M9: פנאי, בילוי ותחביבים
B10: =IF(ROW(E10)<$H$3-$H$5-11,OFFSET(G10,IF(ROW(E10)>=$H$4-5,$H$5-2,0),0),0) -> #N/A | C10: =VLOOKUP(B10,$G$8:$I$138,3,FALSE) -> #N/A | D10: =C10 -> #N/A | G10: =OFFSET(J10,K10,0) -> 0 | I10: =IFERROR(VLOOKUP(G10,'תקציב וביצוע'!$A$1:$L$200,2,FALSE),0) -> 0 | J10: ='תקציב וביצוע'!A4 -> 0 | K10: =IF(NOT(ISERROR(MATCH(OFFSET(J10,K9,0),$M$8:$M$26,0))),K9+1,K9) -> 0 | M10: ביגוד והנעלה
B11: =IF(ROW(E11)<$H$3-$H$5-11,OFFSET(G11,IF(ROW(E11)>=$H$4-5,$H$5-2,0),0),0) -> #N/A | C11: =VLOOKUP(B11,$G$8:$I$138,3,FALSE) -> #N/A | D11: =C11 -> #N/A | G11: =OFFSET(J11,K11,0) -> 0 | I11: =IFERROR(VLOOKUP(G11,'תקציב וביצוע'!$A$1:$L$200,2,FALSE),0) -> 0 | J11: ='תקציב וביצוע'!A5 -> 0 | K11: =IF(NOT(ISERROR(MATCH(OFFSET(J11,K10,0),$M$8:$M$26,0))),K10+1,K10) -> 0 | M11: תכולת בית
B12: =IF(ROW(E12)<$H$3-$H$5-11,OFFSET(G12,IF(ROW(E12)>=$H$4-5,$H$5-2,0),0),0) -> #N/A | C12: =VLOOKUP(B12,$G$8:$I$138,3,FALSE) -> #N/A | D12: =C12 -> #N/A | G12: =OFFSET(J12,K12,0) -> 0 | I12: =IFERROR(VLOOKUP(G12,'תקציב וביצוע'!$A$1:$L$200,2,FALSE),0) -> 0 | J12: ='תקציב וביצוע'!A6 -> 0 | K12: =IF(NOT(ISERROR(MATCH(OFFSET(J12,K11,0),$M$8:$M$26,0))),K11+1,K11) -> 0 | M12: אחזקת בית
B13: =IF(ROW(E13)<$H$3-$H$5-11,OFFSET(G13,IF(ROW(E13)>=$H$4-5,$H$5-2,0),0),0) -> #N/A | C13: =VLOOKUP(B13,$G$8:$I$138,3,FALSE) -> #N/A | D13: =C13 -> #N/A | G13: =OFFSET(J13,K13,0) -> 0 | I13: =IFERROR(VLOOKUP(G13,'תקציב וביצוע'!$A$1:$L$200,2,FALSE),0) -> 0 | J13: ='תקציב וביצוע'!A7 -> 0 | K13: =IF(NOT(ISERROR(MATCH(OFFSET(J13,K12,0),$M$8:$M$26,0))),K12+1,K12) -> 0 | M13: טיפוח
B14: =IF(ROW(E14)<$H$3-$H$5-11,OFFSET(G14,IF(ROW(E14)>=$H$4-5,$H$5-2,0),0),0) -> #N/A | C14: =VLOOKUP(B14,$G$8:$I$138,3,FALSE) -> #N/A | D14: =C14 -> #N/A | G14: =OFFSET(J14,K14,0) -> 0 | I14: =IFERROR(VLOOKUP(G14,'תקציב וביצוע'!$A$1:$L$200,2,FALSE),0) -> 0 | J14: ='תקציב וביצוע'!A8 -> 0 | K14: =IF(NOT(ISERROR(MATCH(OFFSET(J14,K13,0),$M$8:$M$26,0))),K13+1,K13) -> 0 | M14: חינוך
B15: =IF(ROW(E15)<$H$3-$H$5-11,OFFSET(G15,IF(ROW(E15)>=$H$4-5,$H$5-2,0),0),0) -> #N/A | C15: =VLOOKUP(B15,$G$8:$I$138,3,FALSE) -> #N/A | D15: =C15 -> #N/A | G15: =OFFSET(J15,K15,0) -> 0 | I15: =IFERROR(VLOOKUP(G15,'תקציב וביצוע'!$A$1:$L$200,2,FALSE),0) -> 0 | J15: ='תקציב וביצוע'!A9 -> 0 | K15: =IF(NOT(ISERROR(MATCH(OFFSET(J15,K14,0),$M$8:$M$26,0))),K14+1,K14) -> 0 | M15: אירועים, תרומות, צרכי דת
B16: =IF(ROW(E16)<$H$3-$H$5-11,OFFSET(G16,IF(ROW(E16)>=$H$4-5,$H$5-2,0),0),0) -> #N/A | C16: =VLOOKUP(B16,$G$8:$I$138,3,FALSE) -> #N/A | D16: =C16 -> #N/A | G16: =OFFSET(J16,K16,0) -> 0 | I16: =IFERROR(VLOOKUP(G16,'תקציב וביצוע'!$A$1:$L$200,2,FALSE),0) -> 0 | J16: ='תקציב וביצוע'!A10 -> 0 | K16: =IF(NOT(ISERROR(MATCH(OFFSET(J16,K15,0),$M$8:$M$26,0))),K15+1,K15) -> 0 | M16: בריאות
B17: =IF(ROW(E17)<$H$3-$H$5-11,OFFSET(G17,IF(ROW(E17)>=$H$4-5,$H$5-2,0),0),0) -> #N/A | C17: =VLOOKUP(B17,$G$8:$I$138,3,FALSE) -> #N/A | D17: =C17 -> #N/A | G17: =OFFSET(J17,K17,0) -> 0 | I17: =IFERROR(VLOOKUP(G17,'תקציב וביצוע'!$A$1:$L$200,2,FALSE),0) -> 0 | J17: ='תקציב וביצוע'!A11 -> 0 | K17: =IF(NOT(ISERROR(MATCH(OFFSET(J17,K16,0),$M$8:$M$26,0))),K16+1,K16) -> 0 | M17: תחבורה
B18: =IF(ROW(E18)<$H$3-$H$5-11,OFFSET(G18,IF(ROW(E18)>=$H$4-5,$H$5-2,0),0),0) -> #N/A | C18: =VLOOKUP(B18,$G$8:$I$138,3,FALSE) -> #N/A | D18: =C18 -> #N/A | G18: =OFFSET(J18,K18,0) -> 0 | I18: =IFERROR(VLOOKUP(G18,'תקציב וביצוע'!$A$1:$L$200,2,FALSE),0) -> 0 | J18: ='תקציב וביצוע'!A12 -> 0 | K18: =IF(NOT(ISERROR(MATCH(OFFSET(J18,K17,0),$M$8:$M$26,0))),K17+1,K17) -> 0 | M18: משפחה
B19: =IF(ROW(E19)<$H$3-$H$5-11,OFFSET(G19,IF(ROW(E19)>=$H$4-5,$H$5-2,0),0),0) -> #N/A | C19: =VLOOKUP(B19,$G$8:$I$138,3,FALSE) -> #N/A | D19: =C19 -> #N/A | G19: =OFFSET(J19,K19,0) -> 0 | I19: =IFERROR(VLOOKUP(G19,'תקציב וביצוע'!$A$1:$L$200,2,FALSE),0) -> 0 | J19: ='תקציב וביצוע'!A13 -> 0 | K19: =IF(NOT(ISERROR(MATCH(OFFSET(J19,K18,0),$M$8:$M$26,0))),K18+1,K18) -> 0 | M19: תקשורת
... B26: =IF(ROW(E26)<$H$3-$H$5-11,OFFSET(G26,IF(ROW(E26)>=$H$4-5,$H$5-2,0),0),0) -> #N/A | C26: =VLOOKUP(B26,$G$8:$I$138,3,FALSE) -> #N/A | D26: =C26 -> #N/A | G26: =OFFSET(J26,K26,0) -> 0 | I26: =IFERROR(VLOOKUP(G26,'תקציב וביצוע'!$A$1:$L$200,2,FALSE),0) -> 0 | J26: ='תקציב וביצוע'!A20 -> 0 | K26: =IF(NOT(ISERROR(MATCH(OFFSET(J26,K25,0),$M$8:$M$26,0))),K25+1,K25) -> 0 | M26: הכנסות שונות
B27: =IF(ROW(E27)<$H$3-$H$5-11,OFFSET(G27,IF(ROW(E27)>=$H$4-5,$H$5-2,0),0),0) -> #N/A | C27: =VLOOKUP(B27,$G$8:$I$138,3,FALSE) -> #N/A | D27: =C27 -> #N/A | G27: =OFFSET(J27,K27,0) -> 0 | I27: =IFERROR(VLOOKUP(G27,'תקציב וביצוע'!$A$1:$L$200,2,FALSE),0) -> 0 | J27: ='תקציב וביצוע'!A21 -> 0 | K27: =IF(NOT(ISERROR(MATCH(OFFSET(J27,K26,0),$M$8:$M$26,0))),K26+1,K26) -> 0
B28: =IF(ROW(E28)<$H$3-$H$5-11,OFFSET(G28,IF(ROW(E28)>=$H$4-5,$H$5-2,0),0),0) -> #N/A | C28: =VLOOKUP(B28,$G$8:$I$138,3,FALSE) -> #N/A | D28: =C28 -> #N/A | G28: =OFFSET(J28,K28,0) -> 0 | I28: =IFERROR(VLOOKUP(G28,'תקציב וביצוע'!$A$1:$L$200,2,FALSE),0) -> 0 | J28: ='תקציב וביצוע'!A22 -> 0 | K28: =IF(NOT(ISERROR(MATCH(OFFSET(J28,K27,0),$M$8:$M$26,0))),K27+1,K27) -> 0
B29: =IF(ROW(E29)<$H$3-$H$5-11,OFFSET(G29,IF(ROW(E29)>=$H$4-5,$H$5-2,0),0),0) -> #N/A | C29: =VLOOKUP(B29,$G$8:$I$138,3,FALSE) -> #N/A | D29: =C29 -> #N/A | G29: =OFFSET(J29,K29,0) -> 0 | I29: =IFERROR(VLOOKUP(G29,'תקציב וביצוע'!$A$1:$L$200,2,FALSE),0) -> 0 | J29: ='תקציב וביצוע'!A23 -> 0 | K29: =IF(NOT(ISERROR(MATCH(OFFSET(J29,K28,0),$M$8:$M$26,0))),K28+1,K28) -> 0
B30: =IF(ROW(E30)<$H$3-$H$5-11,OFFSET(G30,IF(ROW(E30)>=$H$4-5,$H$5-2,0),0),0) -> #N/A | C30: =VLOOKUP(B30,$G$8:$I$138,3,FALSE) -> #N/A | D30: =C30 -> #N/A | G30: =OFFSET(J30,K30,0) -> 0 | I30: =IFERROR(VLOOKUP(G30,'תקציב וביצוע'!$A$1:$L$200,2,FALSE),0) -> 0 | J30: ='תקציב וביצוע'!A24 -> 0 | K30: =IF(NOT(ISERROR(MATCH(OFFSET(J30,K29,0),$M$8:$M$26,0))),K29+1,K29) -> 0
B31: =IF(ROW(E31)<$H$3-$H$5-11,OFFSET(G31,IF(ROW(E31)>=$H$4-5,$H$5-2,0),0),0) -> #N/A | C31: =VLOOKUP(B31,$G$8:$I$138,3,FALSE) -> #N/A | D31: =C31 -> #N/A | G31: =OFFSET(J31,K31,0) -> 0 | I31: =IFERROR(VLOOKUP(G31,'תקציב וביצוע'!$A$1:$L$200,2,FALSE),0) -> 0 | J31: ='תקציב וביצוע'!A25 -> 0 | K31: =IF(NOT(ISERROR(MATCH(OFFSET(J31,K30,0),$M$8:$M$26,0))),K30+1,K30) -> 0
B32: =IF(ROW(E32)<$H$3-$H$5-11,OFFSET(G32,IF(ROW(E32)>=$H$4-5,$H$5-2,0),0),0) -> #N/A | C32: =VLOOKUP(B32,$G$8:$I$138,3,FALSE) -> #N/A | D32: =C32 -> #N/A | G32: =OFFSET(J32,K32,0) -> 0 | I32: =IFERROR(VLOOKUP(G32,'תקציב וביצוע'!$A$1:$L$200,2,FALSE),0) -> 0 | J32: ='תקציב וביצוע'!A26 -> 0 | K32: =IF(NOT(ISERROR(MATCH(OFFSET(J32,K31,0),$M$8:$M$26,0))),K31+1,K31) -> 0
B33: =IF(ROW(E33)<$H$3-$H$5-11,OFFSET(G33,IF(ROW(E33)>=$H$4-5,$H$5-2,0),0),0) -> #N/A | C33: =VLOOKUP(B33,$G$8:$I$138,3,FALSE) -> #N/A | D33: =C33 -> #N/A | G33: =OFFSET(J33,K33,0) -> 0 | I33: =IFERROR(VLOOKUP(G33,'תקציב וביצוע'!$A$1:$L$200,2,FALSE),0) -> 0 | J33: ='תקציב וביצוע'!A27 -> 0 | K33: =IF(NOT(ISERROR(MATCH(OFFSET(J33,K32,0),$M$8:$M$26,0))),K32+1,K32) -> 0
B34: =IF(ROW(E34)<$H$3-$H$5-11,OFFSET(G34,IF(ROW(E34)>=$H$4-5,$H$5-2,0),0),0) -> #N/A | C34: =VLOOKUP(B34,$G$8:$I$138,3,FALSE) -> #N/A | D34: =C34 -> #N/A | G34: =OFFSET(J34,K34,0) -> 0 | I34: =IFERROR(VLOOKUP(G34,'תקציב וביצוע'!$A$1:$L$200,2,FALSE),0) -> 0 | J34: ='תקציב וביצוע'!A28 -> 0 | K34: =IF(NOT(ISERROR(MATCH(OFFSET(J34,K33,0),$M$8:$M$26,0))),K33+1,K33) -> 0
B35: =IF(ROW(E35)<$H$3-$H$5-11,OFFSET(G35,IF(ROW(E35)>=$H$4-5,$H$5-2,0),0),0) -> #N/A | C35: =VLOOKUP(B35,$G$8:$I$138,3,FALSE) -> #N/A | D35: =C35 -> #N/A | G35: =OFFSET(J35,K35,0) -> 0 | I35: =IFERROR(VLOOKUP(G35,'תקציב וביצוע'!$A$1:$L$200,2,FALSE),0) -> 0 | J35: ='תקציב וביצוע'!A29 -> 0 | K35: =IF(NOT(ISERROR(MATCH(OFFSET(J35,K34,0),$M$8:$M$26,0))),K34+1,K34) -> 0
B36: =IF(ROW(E36)<$H$3-$H$5-11,OFFSET(G36,IF(ROW(E36)>=$H$4-5,$H$5-2,0),0),0) -> #N/A | C36: =VLOOKUP(B36,$G$8:$I$138,3,FALSE) -> #N/A | D36: =C36 -> #N/A | G36: =OFFSET(J36,K36,0) -> 0 | I36: =IFERROR(VLOOKUP(G36,'תקציב וביצוע'!$A$1:$L$200,2,FALSE),0) -> 0 | J36: ='תקציב וביצוע'!A30 -> 0 | K36: =IF(NOT(ISERROR(MATCH(OFFSET(J36,K35,0),$M$8:$M$26,0))),K35+1,K35) -> 0
B37: =IF(ROW(E37)<$H$3-$H$5-11,OFFSET(G37,IF(ROW(E37)>=$H$4-5,$H$5-2,0),0),0) -> #N/A | C37: =VLOOKUP(B37,$G$8:$I$138,3,FALSE) -> #N/A | D37: =C37 -> #N/A | G37: =OFFSET(J37,K37,0) -> 0 | I37: =IFERROR(VLOOKUP(G37,'תקציב וביצוע'!$A$1:$L$200,2,FALSE),0) -> 0 | J37: ='תקציב וביצוע'!A31 -> 0 | K37: =IF(NOT(ISERROR(MATCH(OFFSET(J37,K36,0),$M$8:$M$26,0))),K36+1,K36) -> 0
B38: =IF(ROW(E38)<$H$3-$H$5-11,OFFSET(G38,IF(ROW(E38)>=$H$4-5,$H$5-2,0),0),0) -> #N/A | C38: =VLOOKUP(B38,$G$8:$I$138,3,FALSE) -> #N/A | D38: =C38 -> #N/A | G38: =OFFSET(J38,K38,0) -> 0 | I38: =IFERROR(VLOOKUP(G38,'תקציב וביצוע'!$A$1:$L$200,2,FALSE),0) -> 0 | J38: ='תקציב וביצוע'!A32 -> 0 | K38: =IF(NOT(ISERROR(MATCH(OFFSET(J38,K37,0),$M$8:$M$26,0))),K37+1,K37) -> 0
... B138: =IF(ROW(E138)<$H$3-$H$5-11,OFFSET(G138,IF(ROW(E138)>=$H$4-5,$H$5-2,0),0),0) -> #N/A | C138: =VLOOKUP(B138,$G$8:$I$138,3,FALSE) -> #N/A | D138: =C138 -> #N/A | G138: =OFFSET(J138,K138,0) -> 0 | I138: =IFERROR(VLOOKUP(G138,'תקציב וביצוע'!$A$1:$L$200,2,FALSE),0) -> 0 | J138: ='תקציב וביצוע'!A132 -> 0 | K138: =IF(NOT(ISERROR(MATCH(OFFSET(J138,K137,0),$M$8:$M$26,0))),K137+1,K137) -> 0
C139: =SUM(C8:C138) -> #N/A | D139: =SUM(D8:D138) -> #N/A | G139: =OFFSET(J139,K139,0) -> 0 | I139: =IFERROR(VLOOKUP(G139,'תקציב וביצוע'!$A$1:$L$200,2,FALSE),0) -> 0 | J139: ='תקציב וביצוע'!A133 -> 0 | K139: =IF(NOT(ISERROR(MATCH(OFFSET(J139,K138,0),$M$8:$M$26,0))),K138+1,K138) -> 0
A140: ='תקציב וביצוע'!A64 -> 0 | G140: =OFFSET(J140,K140,0) -> 0 | I140: =IFERROR(VLOOKUP(G140,'תקציב וביצוע'!$A$1:$L$200,2,FALSE),0) -> 0 | J140: ='תקציב וביצוע'!A134 -> 0 | K140: =IF(NOT(ISERROR(MATCH(OFFSET(J140,K139,0),$M$8:$M$26,0))),K139+1,K139) -> 0
B141: הכנסות | G141: =OFFSET(J141,K141,0) -> 0 | I141: =IFERROR(VLOOKUP(G141,'תקציב וביצוע'!$A$1:$L$200,2,FALSE),0) -> 0 | J141: ='תקציב וביצוע'!A135 -> 0 | K141: =IF(NOT(ISERROR(MATCH(OFFSET(J141,K140,0),$M$8:$M$26,0))),K140+1,K140) -> 0
B142: =IF(ROW(E142)<156-18+$H$6,OFFSET(G8,MATCH("הכנסות",$G$8:$G$163,FALSE),0),0) -> #N/A | C142: =VLOOKUP(B142,$G$8:$I$164,3,FALSE) -> #N/A | D142: =C142 -> #N/A | G142: =OFFSET(J142,K142,0) -> 0 | I142: =IFERROR(VLOOKUP(G142,'תקציב וביצוע'!$A$1:$L$200,2,FALSE),0) -> 0 | J142: ='תקציב וביצוע'!A136 -> 0 | K142: =IF(NOT(ISERROR(MATCH(OFFSET(J142,K141,0),$M$8:$M$26,0))),K141+1,K141) -> 0
B143: =IF(ROW(E143)<156-18+$H$6,OFFSET(G9,MATCH("הכנסות",$G$8:$G$163,FALSE),0),0) -> #N/A | C143: =VLOOKUP(B143,$G$8:$I$164,3,FALSE) -> #N/A | D143: =C143 -> #N/A | G143: =OFFSET(J143,K143,0) -> 0 | I143: =IFERROR(VLOOKUP(G143,'תקציב וביצוע'!$A$1:$L$200,2,FALSE),0) -> 0 | J143: ='תקציב וביצוע'!A137 -> 0 | K143: =IF(NOT(ISERROR(MATCH(OFFSET(J143,K142,0),$M$8:$M$26,0))),K142+1,K142) -> 0
B144: =IF(ROW(E144)<156-18+$H$6,OFFSET(G10,MATCH("הכנסות",$G$8:$G$163,FALSE),0),0) -> #N/A | C144: =VLOOKUP(B144,$G$8:$I$164,3,FALSE) -> #N/A | D144: =C144 -> #N/A | G144: =OFFSET(J144,K144,0) -> 0 | I144: =IFERROR(VLOOKUP(G144,'תקציב וביצוע'!$A$1:$L$200,2,FALSE),0) -> 0 | J144: ='תקציב וביצוע'!A138 -> 0 | K144: =IF(NOT(ISERROR(MATCH(OFFSET(J144,K143,0),$M$8:$M$26,0))),K143+1,K143) -> 0
B145: =IF(ROW(E145)<156-18+$H$6,OFFSET(G11,MATCH("הכנסות",$G$8:$G$163,FALSE),0),0) -> #N/A | C145: =VLOOKUP(B145,$G$8:$I$164,3,FALSE) -> #N/A | D145: =C145 -> #N/A | G145: =OFFSET(J145,K145,0) -> 0 | I145: =IFERROR(VLOOKUP(G145,'תקציב וביצוע'!$A$1:$L$200,2,FALSE),0) -> 0 | J145: ='תקציב וביצוע'!A139 -> 0 | K145: =IF(NOT(ISERROR(MATCH(OFFSET(J145,K144,0),$M$8:$M$26,0))),K144+1,K144) -> 0
...

Sheet תכנון הבראה
A1: ="תכנון הבראה - "&Family -> תכנון הבראה - 0
A2: יש למלא רק את השדות עם הטקסט הכחול
B4: חודש | C4: שנה | U4: תפריט חובות בהסדר | X4: תפריט חובות שלא בהסדר
A5: תחילת תכנית הבראה | B5: =IF(MONTH(CurrDate)=12,1,MONTH(CurrDate)+1) -> 2 | C5: =YEAR(CurrDate) -> 1900 | U5: פעולה | V5: קוד | X5: פעולה | Y5: קוד
U6: ללא שינוי | V6: 0 | X6: ללא שינוי | Y6: 0
A7: שלב 1: תכנון תקציב | U7: פרעון מלא | V7: 1 | X7: פרעון מלא | Y7: 1
C8: תקציב נוכחי | D8: תקציב מוצע | E8: תקציב מוצע 2 | F8: תקציב מוצע 3 | U8: הקפאה | V8: 2 | X8: =U9 -> פריסה מחדש | Y8: =V9 -> 3
B9: הכנסות | C9: =CurrentIncome -> #N/A | D9: ='תקציב להבראה'!D165 -> #N/A | E9: =D9 -> #N/A | F9: =E9 -> #N/A | U9: פריסה מחדש | V9: 3
B10: הוצאות | C10: =CurrentOutgo -> #N/A | D10: ='תקציב להבראה'!D139 -> #N/A | E10: =D10 -> #N/A | F10: =E10 -> #N/A | U10: ויתור חלקי | V10: 4
B11: הפרש | C11: =C9-C10 -> #N/A | D11: =D9-D10 -> #N/A | E11: =E9-E10 -> #N/A | F11: =F9-F10 -> #N/A | U11: ויתור מלא | V11: 5
B12: מחודש | D12: 1 | E12: =D13+1 -> 13 | F12: =E13+1 -> 25
B13: עד חודש | D13: 12 | E13: 24 | F13: 999
A16: שלב 2: כספים זמינים (חסכונות, פדיון פיצויים, מענקי הבראה וכו')
B17: סכום | C17: סכום למשיכה | D17: מועד משיכה | E17: הערות
A18: קרן השתלמות
B19: 0
B20: 0
B21: 0
A22: סה"כ | B22: =SUM(B18:B21) -> 0 | C22: =SUM(C18:C21) -> 0 | F22: סה"כ זמין מיידי | G22: =SUMPRODUCT((D18:D21<=DATE(C5,B5+1,0)+(D18:D21=0))*C18:C21) -> 0
A25: שלב 3: הלוואות זמינות
A26: הלוואה חדשה
B27: סכום | D27: חודשי גרייס | E27: ריבית | F27: מס' חודשים | G27: החזר חודשי | H27: הערות | J27: תשלום בתקופת הגרייס
A28: הלוואה 1 | B28: 0 | G28: =IF(ISERROR(-PMT(E28/12,F28,B28)),0,-PMT(E28/12,F28,B28*IF(I28="מלא",(1+E28/12)^(D28),1))) -> 0
A29: הלוואה 2 | B29: 0 | G29: =IF(ISERROR(-PMT(E29/12,F29,B29)),0,-PMT(E29/12,F29,B29*IF(I29="מלא",(1+E29/12)^(D29),1))) -> 0
A30: הלוואה 3 | B30: 0 | G30: =IF(ISERROR(-PMT(E30/12,F30,B30)),0,-PMT(E30/12,F30,B30*IF(I30="מלא",(1+E30/12)^(D30),1))) -> 0
A31: הלוואה 4 | B31: 0 | G31: =IF(ISERROR(-PMT(E31/12,F31,B31)),0,-PMT(E31/12,F31,B31*IF(I31="מלא",(1+E31/12)^(D31),1))) -> 0
A32: הלוואה 5 | B32: 0 | G32: =IF(ISERROR(-PMT(E32/12,F32,B32)),0,-PMT(E32/12,F32,B32*IF(I32="מלא",(1+E32/12)^(D32),1))) -> 0
A33: הלוואה 6 | B33: 0 | G33: =IF(ISERROR(-PMT(E33/12,F33,B33)),0,-PMT(E33/12,F33,B33*IF(I33="מלא",(1+E33/12)^(D33),1))) -> 0
A34: הלוואה 7 | B34: 0 | G34: =IF(ISERROR(-PMT(E34/12,F34,B34)),0,-PMT(E34/12,F34,B34*IF(I34="מלא",(1+E34/12)^(D34),1))) -> 0
A35: הלוואה 8 | B35: 0 | G35: =IF(ISERROR(-PMT(E35/12,F35,B35)),0,-PMT(E35/12,F35,B35*IF(I35="מלא",(1+E35/12)^(D35),1))) -> 0
A36: הלוואה 9 | B36: 0 | G36: =IF(ISERROR(-PMT(E36/12,F36,B36)),0,-PMT(E36/12,F36,B36*IF(I36="מלא",(1+E36/12)^(D36),1))) -> 0
A37: הלוואה 10 | B37: 0 | G37: =IF(ISERROR(-PMT(E37/12,F37,B37)),0,-PMT(E37/12,F37,B37*IF(I37="מלא",(1+E37/12)^(D37),1))) -> 0
A38: סה"כ | B38: =SUM(B28:B37) -> 0 | F38: סה"כ זמין מיידי | G38: =LoanTotal -> 0
A41: בדיקת ביניים - מבצעים תוך כדי ההחלטה אודות פרעונות בשלב 4 ו-5 | F41: סכום זמין לפרעונות | G41: =G22+G38 -> 0
A42: בודקים אם יש מספיק כסף זמין מחסכונות והלוואות כדי לפרוע את המתוכנן | F42: מתוכנן לפרעון | G42: =SUMPRODUCT(($H$46:$H$78='תכנון הבראה'!U7)*($I$46:$I$78))+H117 -> 0
F43: עודף \ חוסר | G43: =G41-G42 -> 0
A44: שלב 4: טיפול בחובות שבהסדר
A45: טיפול בהלוואות קיימות | B45: יתרה | C45: החזר חודשי | D45: מס' חודשים | E45: ריבית | F45: יחס החזר ליתרה | G45: עדיפות לטיפול | H45: פעולה | I45: סכום פרעון מלא | J45: תקופה בחודשים | K45: חודשי הקפאה | L45: תשלום | M45: סכום וויתור
A46: =IF('פריסת חובות'!A9<>"",'פריסת חובות'!A9,"") | B46: ='פריסת חובות'!B9 -> 0 | C46: ='פריסת חובות'!C9 -> 0 | D46: =IF($A46="","",COUNTIF('פריסת חובות'!E9:CZ9,">0")) | E46: ='פריסת חובות'!D9 -> 0 | F46: =IF($A46="","",C46/B46) | G46: =IF($A46="","",RANK(F46,$F$46:$F$72,0)) | L46: =IF(H46='תכנון הבראה'!$U$9,-PMT(E46/12,J46,B46),0) -> 0
A47: =IF('פריסת חובות'!A10<>"",'פריסת חובות'!A10,"") | B47: ='פריסת חובות'!B10 -> 0 | C47: ='פריסת חובות'!C10 -> 0 | D47: =IF($A47="","",COUNTIF('פריסת חובות'!E10:CZ10,">0")) | E47: ='פריסת חובות'!D10 -> 0 | F47: =IF($A47="","",C47/B47) | G47: =IF($A47="","",RANK(F47,$F$46:$F$72,0)) | L47: =IF(H47='תכנון הבראה'!$U$9,-PMT(E47/12,J47,B47),0) -> 0
...

Sheet סיכום ויזואלי
A1: ="סיכום תכנית הבראה "&חובות!B3 -> סיכום תכנית הבראה
A3: סטטיסטיקות ותרשימים
C4: חודשים | D4: שנים | F4: סכום זמין לפרעון חובות מיידית (מגיע מחסכונות והלוואות חדשות) | I4: ='תכנון הבראה'!G41 -> 0
A5: זמן עד לסיום חובות שבהסדר כולל שימוש בעודפים | C5: =SUMPRODUCT(('סיכום תוצאות'!E157:CZ157>0)*1) -> #N/A | D5: =C5/12 -> #N/A | F5: סך החובות שייפרעו מיידית | I5: =PeraonTotal -> 0
A6: זמן עד לסיום חובות שלא בהסדר כולל שימוש בעודפים | C6: =IF( 'סיכום תוצאות'!CZ156 > 0, -1, SUMPRODUCT(('סיכום תוצאות'!E156:CZ156>0)*1)) -> #N/A | D6: =IF(C6<0, "יותר מ 10", C6/12) -> #N/A | F6: עודפי חסכונות והלוואות על פרעונות בחודש הראשון | I6: =I4-I5 -> 0
A7: זמן עד לסיום מלוא החובות כולל שימוש בעודפים | C7: =IF(C6=-1, C6, MAX(C5:C6)) -> #N/A | D7: =IF(C7<0, "יותר מ 10", C7/12) -> #N/A | F7: חוסר תזרימי מצטבר בתחילת ההבראה (הלוואה אפשרית מפעמונים) | I7: =-MIN('סיכום תוצאות'!E159:CZ159) -> #N/A
F8: עודפי מצטבר בתחילת הבראה (יכולת החזר חודשי גבוהה יותר) | I8: =IFERROR(INDEX('סיכום תוצאות'!E160:CZ160, 1, C7),'סיכום תוצאות'!CZ160) -> #N/A
F9: חובות שלא בהסדר בחודש הראשון | I9: ='סיכום תוצאות'!D156 -> 0

Sheet סיכום תוצאות
A1: ="סיכום תכנית הבראה "&חובות!B3 -> סיכום תכנית הבראה
E2: 1 | F2: 2 | G2: 3 | H2: 4 | I2: 5 | J2: 6 | K2: 7 | L2: 8 | M2: 9 | N2: 10 | O2: 11 | P2: 12 | Q2: 13 | R2: 14 | S2: 15 | T2: 16 | U2: 17 | V2: 18 | W2: 19 | X2: 20 | Y2: 21 | Z2: 22 | AA2: 23 | AB2: 24 | AC2: 25 | AD2: 26 | AE2: 27 | AF2: 28 | AG2: 29 | AH2: 30 | AI2: 31 | AJ2: 32 | AK2: 33 | AL2: 34 | AM2: 35 | AN2: 36 | AO2: 37 | AP2: 38 | AQ2: 39 | AR2: 40 | AS2: 41 | AT2: 42 | AU2: 43 | AV2: 44 | AW2: 45 | AX2: 46 | AY2: 47 | AZ2: 48 | BA2: 49 | BB2: 50 | BC2: 51 | BD2: 52 | BE2: 53 | BF2: 54 | BG2: 55 | BH2: 56 | BI2: 57 | BJ2: 58 | BK2: 59 | BL2: 60 | BM2: 61 | BN2: 62 | BO2: 63 | BP2: 64 | BQ2: 65 | BR2: 66 | BS2: 67 | BT2: 68 | BU2: 69 | BV2: 70 | BW2: 71 | BX2: 72 | BY2: 73 | BZ2: 74 | CA2: 75 | CB2: 76 | CC2: 77 | CD2: 78 | CE2: 79 | CF2: 80 | CG2: 81 | CH2: 82 | CI2: 83 | CJ2: 84 | CK2: 85 | CL2: 86 | CM2: 87 | CN2: 88 | CO2: 89 | CP2: 90 | CQ2: 91 | CR2: 92 | CS2: 93 | CT2: 94 | CU2: 95 | CV2: 96 | CW2: 97 | CX2: 98 | CY2: 99 | CZ2: 100
A3: ניתוח התזרים החודשי
A5: חודש | E5: ='פריסת חובות'!E8 -> 32 | F5: ='פריסת חובות'!F8 -> 61 | G5: ='פריסת חובות'!G8 -> 92 | H5: ='פריסת חובות'!H8 -> 122 | I5: ='פריסת חובות'!I8 -> 153 | J5: ='פריסת חובות'!J8 -> 183 | K5: ='פריסת חובות'!K8 -> 214 | L5: ='פריסת חובות'!L8 -> 245 | ... CZ5: ='פריסת חובות'!CZ8 -> 3044
A6: מצב נוכחי
A7: הכנסות | E7: =CurrentIncome -> #N/A | F7: =CurrentIncome -> #N/A | G7: =CurrentIncome -> #N/A | H7: =CurrentIncome -> #N/A | I7: =CurrentIncome -> #N/A | J7: =CurrentIncome -> #N/A | K7: =CurrentIncome -> #N/A | L7: =CurrentIncome -> #N/A | ... CZ7: =CurrentIncome -> #N/A
A8: הוצאות | E8: =CurrentOutgo -> #N/A | F8: =CurrentOutgo -> #N/A | G8: =CurrentOutgo -> #N/A | H8: =CurrentOutgo -> #N/A | I8: =CurrentOutgo -> #N/A | J8: =CurrentOutgo -> #N/A | K8: =CurrentOutgo -> #N/A | L8: =CurrentOutgo -> #N/A | ... CZ8: =CurrentOutgo -> #N/A
A9: סכום פנוי להחזר חובות | E9: =E7-E8 -> #N/A | F9: =F7-F8 -> #N/A | G9: =G7-G8 -> #N/A | H9: =H7-H8 -> #N/A | I9: =I7-I8 -> #N/A | J9: =J7-J8 -> #N/A | K9: =K7-K8 -> #N/A | L9: =L7-L8 -> #N/A | ... CZ9: =CZ7-CZ8 -> #N/A
A10: החזר | E10: ='פריסת חובות'!E42 -> 0 | F10: ='פריסת חובות'!F42 -> 0 | G10: ='פריסת חובות'!G42 -> 0 | H10: ='פריסת חובות'!H42 -> 0 | I10: ='פריסת חובות'!I42 -> 0 | J10: ='פריסת חובות'!J42 -> 0 | K10: ='פריסת חובות'!K42 -> 0 | L10: ='פריסת חובות'!L42 -> 0 | ... CZ10: ='פריסת חובות'!CZ42 -> 0
A11: הכנסות פחות הוצאות והחזר חובות לפני הבראה | E11: =+E9-E10 -> #N/A | F11: =+F9-F10 -> #N/A | G11: =+G9-G10 -> #N/A | H11: =+H9-H10 -> #N/A | I11: =+I9-I10 -> #N/A | J11: =+J9-J10 -> #N/A | K11: =+K9-K10 -> #N/A | L11: =+L9-L10 -> #N/A | ... CZ11: =+CZ9-CZ10 -> #N/A
A13: מצב חדש
A14: הכנסות | E14: =INDEX('תכנון הבראה'!$D$9:$F$9,1,MATCH(E$17,'תכנון הבראה'!$D$12:$F$12,1)) -> #N/A | F14: =INDEX('תכנון הבראה'!$D$9:$F$9,1,MATCH(F$17,'תכנון הבראה'!$D$12:$F$12,1)) -> #N/A | G14: =INDEX('תכנון הבראה'!$D$9:$F$9,1,MATCH(G$17,'תכנון הבראה'!$D$12:$F$12,1)) -> #N/A | H14: =INDEX('תכנון הבראה'!$D$9:$F$9,1,MATCH(H$17,'תכנון הבראה'!$D$12:$F$12,1)) -> #N/A | I14: =INDEX('תכנון הבראה'!$D$9:$F$9,1,MATCH(I$17,'תכנון הבראה'!$D$12:$F$12,1)) -> #N/A | J14: =INDEX('תכנון הבראה'!$D$9:$F$9,1,MATCH(J$17,'תכנון הבראה'!$D$12:$F$12,1)) -> #N/A | K14: =INDEX('תכנון הבראה'!$D$9:$F$9,1,MATCH(K$17,'תכנון הבראה'!$D$12:$F$12,1)) -> #N/A | L14: =INDEX('תכנון הבראה'!$D$9:$F$9,1,MATCH(L$17,'תכנון הבראה'!$D$12:$F$12,1)) -> #N/A | ... CZ14: =INDEX('תכנון הבראה'!$D$9:$F$9,1,MATCH(CZ$17,'תכנון הבראה'!$D$12:$F$12,1)) -> #N/A
A15: הוצאות | E15: =INDEX('תכנון הבראה'!$D$10:$F$10,1,MATCH(E$17,'תכנון הבראה'!$D$12:$F$12,1)) -> #N/A | F15: =INDEX('תכנון הבראה'!$D$10:$F$10,1,MATCH(F$17,'תכנון הבראה'!$D$12:$F$12,1)) -> #N/A | G15: =INDEX('תכנון הבראה'!$D$10:$F$10,1,MATCH(G$17,'תכנון הבראה'!$D$12:$F$12,1)) -> #N/A | H15: =INDEX('תכנון הבראה'!$D$10:$F$10,1,MATCH(H$17,'תכנון הבראה'!$D$12:$F$12,1)) -> #N/A | I15: =INDEX('תכנון הבראה'!$D$10:$F$10,1,MATCH(I$17,'תכנון הבראה'!$D$12:$F$12,1)) -> #N/A | J15: =INDEX('תכנון הבראה'!$D$10:$F$10,1,MATCH(J$17,'תכנון הבראה'!$D$12:$F$12,1)) -> #N/A | K15: =INDEX('תכנון הבראה'!$D$10:$F$10,1,MATCH(K$17,'תכנון הבראה'!$D$12:$F$12,1)) -> #N/A | L15: =INDEX('תכנון הבראה'!$D$10:$F$10,1,MATCH(L$17,'תכנון הבראה'!$D$12:$F$12,1)) -> #N/A | ... CZ15: =INDEX('תכנון הבראה'!$D$10:$F$10,1,MATCH(CZ$17,'תכנון הבראה'!$D$12:$F$12,1)) -> #N/A
A16: סכום פנוי להחזר חובות | E16: =E14-E15 -> #N/A | F16: =F14-F15 -> #N/A | G16: =G14-G15 -> #N/A | H16: =H14-H15 -> #N/A | I16: =I14-I15 -> #N/A | J16: =J14-J15 -> #N/A | K16: =K14-K15 -> #N/A | L16: =L14-L15 -> #N/A | ... CZ16: =CZ14-CZ15 -> #N/A
A17: הלוואות בהסדר אחרי הטמעת תכנית ההבראה | E17: 1 | F17: =E17+1 -> 2 | G17: =F17+1 -> 3 | H17: =G17+1 -> 4 | I17: =H17+1 -> 5 | J17: =I17+1 -> 6 | K17: =J17+1 -> 7 | L17: =K17+1 -> 8 | M17: =L17+1 -> 9 | ... CZ17: =CY17+1 -> 100
A18: ='תכנון הבראה'!A46 | B18: ='תכנון הבראה'!H46 -> 0 | C18: =IF(ISERROR(VLOOKUP(B18,LoanOptions,2,0)),0,VLOOKUP(B18,LoanOptions,2,0)) -> 0 | E18: =IF($A18="",0,($C18=0)*'פריסת חובות'!E9 +($C18=1)*0+ ($C18=2)*IF(E$17<='תכנון הבראה'!$K46,0,OFFSET('פריסת חובות'!E9,0,-'תכנון הבראה'!$K46))*(1+'תכנון הבראה'!$E46)^('תכנון הבראה'!$K46/12)+ ($C18=3)*'תכנון הבראה'!$L46*(E$17<='תכנון הבראה'!$J46))+ IF($C18=4,(1-'תכנון הבראה'!$M46/'תכנון הבראה'!$B46)*'תכנון הבראה'!$C46,0)*(E$17<='תכנון הבראה'!$D46) -> 0 | F18: =IF($A18="",0,($C18=0)*'פריסת חובות'!F9 +($C18=1)*0+ ($C18=2)*IF(F$17<='תכנון הבראה'!$K46,0,OFFSET('פריסת חובות'!F9,0,-'תכנון הבראה'!$K46))*(1+'תכנון הבראה'!$E46)^('תכנון הבראה'!$K46/12)+ ($C18=3)*'תכנון הבראה'!$L46*(F$17<='תכנון הבראה'!$J46))+ IF($C18=4,(1-'תכנון הבראה'!$M46/'תכנון הבראה'!$B46)*'תכנון הבראה'!$C46,0)*(F$17<='תכנון הבראה'!$D46) -> 0 | G18: =IF($A18="",0,($C18=0)*'פריסת חובות'!G9 +($C18=1)*0+ ($C18=2)*IF(G$17<='תכנון הבראה'!$K46,0,OFFSET('פריסת חובות'!G9,0,-'תכנון הבראה'!$K46))*(1+'תכנון הבראה'!$E46)^('תכנון הבראה'!$K46/12)+ ($C18=3)*'תכנון הבראה'!$L46*(G$17<='תכנון הבראה'!$J46))+ IF($C18=4,(1-'תכנון הבראה'!$M46/'תכנון הבראה'!$B46)*'תכנון הבראה'!$C46,0)*(G$17<='תכנון הבראה'!$D46) -> 0 | H18: =IF($A18="",0,($C18=0)*'פריסת חובות'!H9 +($C18=1)*0+ ($C18=2)*IF(H$17<='תכנון הבראה'!$K46,0,OFFSET('פריסת חובות'!H9,0,-'תכנון הבראה'!$K46))*(1+'תכנון הבראה'!$E46)^('תכנון הבראה'!$K46/12)+ ($C18=3)*'תכנון הבראה'!$L46*(H$17<='תכנון הבראה'!$J46))+ IF($C18=4,(1-'תכנון הבראה'!$M46/'תכנון הבראה'!$B46)*'תכנון הבראה'!$C46,0)*(H$17<='תכנון הבראה'!$D46) -> 0 | I18: =IF($A18="",0,($C18=0)*'פריסת חובות'!I9 +($C18=1)*0+ ($C18=2)*IF(I$17<='תכנון הבראה'!$K46,0,OFFSET('פריסת חובות'!I9,0,-'תכנון הבראה'!$K46))*(1+'תכנון הבראה'!$E46)^('תכנון הבראה'!$K46/12)+ ($C18=3)*'תכנון הבראה'!$L46*(I$17<='תכנון הבראה'!$J46))+ IF($C18=4,(1-'תכנון הבראה'!$M46/'תכנון הבראה'!$B46)*'תכנון הבראה'!$C46,0)*(I$17<='תכנון הבראה'!$D46) -> 0 | J18: =IF($A18="",0,($C18=0)*'פריסת חובות'!J9 +($C18=1)*0+ ($C18=2)*IF(J$17<='תכנון הבראה'!$K46,0,OFFSET('פריסת חובות'!J9,0,-'תכנון הבראה'!$K46))*(1+'תכנון הבראה'!$E46)^('תכנון הבראה'!$K46/12)+ ($C18=3)*'תכנון הבראה'!$L46*(J$17<='תכנון הבראה'!$J46))+ IF($C18=4,(1-'תכנון הבראה'!$M46/'תכנון הבראה'!$B46)*'תכנון הבראה'!$C46,0)*(J$17<='תכנון הבראה'!$D46) -> 0 | K18: =IF($A18="",0,($C18=0)*'פריסת חובות'!K9 +($C18=1)*0+ ($C18=2)*IF(K$17<='תכנון הבראה'!$K46,0,OFFSET('פריסת חובות'!K9,0,-'תכנון הבראה'!$K46))*(1+'תכנון הבראה'!$E46)^('תכנון הבראה'!$K46/12)+ ($C18=3)*'תכנון הבראה'!$L46*(K$17<='תכנון הבראה'!$J46))+ IF($C18=4,(1-'תכנון הבראה'!$M46/'תכנון הבראה'!$B46)*'תכנון הבראה'!$C46,0)*(K$17<='תכנון הבראה'!$D46) -> 0 | L18: =IF($A18="",0,($C18=0)*'פריסת חובות'!L9 +($C18=1)*0+ ($C18=2)*IF(L$17<='תכנון הבראה'!$K46,0,OFFSET('פריסת חובות'!L9,0,-'תכנון הבראה'!$K46))*(1+'תכנון הבראה'!$E46)^('תכנון הבראה'!$K46/12)+ ($C18=3)*'תכנון הבראה'!$L46*(L$17<='תכנון הבראה'!$J46))+ IF($C18=4,(1-'תכנון הבראה'!$M46/'תכנון הבראה'!$B46)*'תכנון הבראה'!$C46,0)*(L$17<='תכנון הבראה'!$D46) -> 0 | ... CZ18: =IF($A18="",0,($C18=0)*'פריסת חובות'!CZ9 +($C18=1)*0+ ($C18=2)*IF(CZ$17<='תכנון הבראה'!$K46,0,OFFSET('פריסת חובות'!CZ9,0,-'תכנון הבראה'!$K46))*(1+'תכנון הבראה'!$E46)^('תכנון הבראה'!$K46/12)+ ($C18=3)*'תכנון הבראה'!$L46*(CZ$17<='תכנון הבראה'!$J46))+ IF($C18=4,(1-'תכנון הבראה'!$M46/'תכנון הבראה'!$B46)*'תכנון הבראה'!$C46,0)*(CZ$17<='תכנון הבראה'!$D46) -> 0
A19: ='תכנון הבראה'!A47 | B19: ='תכנון הבראה'!H47 -> 0 | C19: =IF(ISERROR(VLOOKUP(B19,LoanOptions,2,0)),0,VLOOKUP(B19,LoanOptions,2,0)) -> 0 | E19: =IF($A19="",0,($C19=0)*'פריסת חובות'!E10 +($C19=1)*0+ ($C19=2)*IF(E$17<='תכנון הבראה'!$K47,0,OFFSET('פריסת חובות'!E10,0,-'תכנון הבראה'!$K47))*(1+'תכנון הבראה'!$E47)^('תכנון הבראה'!$K47/12)+ ($C19=3)*'תכנון הבראה'!$L47*(E$17<='תכנון הבראה'!$J47))+ IF($C19=4,(1-'תכנון הבראה'!$M47/'תכנון הבראה'!$B47)*'תכנון הבראה'!$C47,0)*(E$17<='תכנון הבראה'!$D47) -> 0 | F19: =IF($A19="",0,($C19=0)*'פריסת חובות'!F10 +($C19=1)*0+ ($C19=2)*IF(F$17<='תכנון הבראה'!$K47,0,OFFSET('פריסת חובות'!F10,0,-'תכנון הבראה'!$K47))*(1+'תכנון הבראה'!$E47)^('תכנון הבראה'!$K47/12)+ ($C19=3)*'תכנון הבראה'!$L47*(F$17<='תכנון הבראה'!$J47))+ IF($C19=4,(1-'תכנון הבראה'!$M47/'תכנון הבראה'!$B47)*'תכנון הבראה'!$C47,0)*(F$17<='תכנון הבראה'!$D47) -> 0 | G19: =IF($A19="",0,($C19=0)*'פריסת חובות'!G10 +($C19=1)*0+ ($C19=2)*IF(G$17<='תכנון הבראה'!$K47,0,OFFSET('פריסת חובות'!G10,0,-'תכנון הבראה'!$K47))*(1+'תכנון הבראה'!$E47)^('תכנון הבראה'!$K47/12)+ ($C19=3)*'תכנון הבראה'!$L47*(G$17<='תכנון הבראה'!$J47))+ IF($C19=4,(1-'תכנון הבראה'!$M47/'תכנון הבראה'!$B47)*'תכנון הבראה'!$C47,0)*(G$17<='תכנון הבראה'!$D47) -> 0 | H19: =IF($A19="",0,($C19=0)*'פריסת חובות'!H10 +($C19=1)*0+ ($C19=2)*IF(H$17<='תכנון הבראה'!$K47,0,OFFSET('פריסת חובות'!H10,0,-'תכנון הבראה'!$K47))*(1+'תכנון הבראה'!$E47)^('תכנון הבראה'!$K47/12)+ ($C19=3)*'תכנון הבראה'!$L47*(H$17<='תכנון הבראה'!$J47))+ IF($C19=4,(1-'תכנון הבראה'!$M47/'תכנון הבראה'!$B47)*'תכנון הבראה'!$C47,0)*(H$17<='תכנון הבראה'!$D47) -> 0 | I19: =IF($A19="",0,($C19=0)*'פריסת חובות'!I10 +($C19=1)*0+ ($C19=2)*IF(I$17<='תכנון הבראה'!$K47,0,OFFSET('פריסת חובות'!I10,0,-'תכנון הבראה'!$K47))*(1+'תכנון הבראה'!$E47)^('תכנון הבראה'!$K47/12)+ ($C19=3)*'תכנון הבראה'!$L47*(I$17<='תכנון הבראה'!$J47))+ IF($C19=4,(1-'תכנון הבראה'!$M47/'תכנון הבראה'!$B47)*'תכנון הבראה'!$C47,0)*(I$17<='תכנון הבראה'!$D47) -> 0 | J19: =IF($A19="",0,($C19=0)*'פריסת חובות'!J10 +($C19=1)*0+ ($C19=2)*IF(J$17<='תכנון הבראה'!$K47,0,OFFSET('פריסת חובות'!J10,0,-'תכנון הבראה'!$K47))*(1+'תכנון הבראה'!$E47)^('תכנון הבראה'!$K47/12)+ ($C19=3)*'תכנון הבראה'!$L47*(J$17<='תכנון הבראה'!$J47))+ IF($C19=4,(1-'תכנון הבראה'!$M47/'תכנון הבראה'!$B47)*'תכנון הבראה'!$C47,0)*(J$17<='תכנון הבראה'!$D47) -> 0 | K19: =IF($A19="",0,($C19=0)*'פריסת חובות'!K10 +($C19=1)*0+ ($C19=2)*IF(K$17<='תכנון הבראה'!$K47,0,OFFSET('פריסת חובות'!K10,0,-'תכנון הבראה'!$K47))*(1+'תכנון הבראה'!$E47)^('תכנון הבראה'!$K47/12)+ ($C19=3)*'תכנון הבראה'!$L47*(K$17<='תכנון הבראה'!$J47))+ IF($C19=4,(1-'תכנון הבראה'!$M47/'תכנון הבראה'!$B47)*'תכנון הבראה'!$C47,0)*(K$17<='תכנון הבראה'!$D47) -> 0 | L19: =IF($A19="",0,($C19=0)*'פריסת חובות'!L10 +($C19=1)*0+ ($C19=2)*IF(L$17<='תכנון הבראה'!$K47,0,OFFSET('פריסת חובות'!L10,0,-'תכנון הבראה'!$K47))*(1+'תכנון הבראה'!$E47)^('תכנון הבראה'!$K47/12)+ ($C19=3)*'תכנון הבראה'!$L47*(L$17<='תכנון הבראה'!$J47))+ IF($C19=4,(1-'תכנון הבראה'!$M47/'תכנון הבראה'!$B47)*'תכנון הבראה'!$C47,0)*(L$17<='תכנון הבראה'!$D47) -> 0 | ... CZ19: =IF($A19="",0,($C19=0)*'פריסת חובות'!CZ10 +($C19=1)*0+ ($C19=2)*IF(CZ$17<='תכנון הבראה'!$K47,0,OFFSET('פריסת חובות'!CZ10,0,-'תכנון הבראה'!$K47))*(1+'תכנון הבראה'!$E47)^('תכנון הבראה'!$K47/12)+ ($C19=3)*'תכנון הבראה'!$L47*(CZ$17<='תכנון הבראה'!$J47))+ IF($C19=4,(1-'תכנון הבראה'!$M47/'תכנון הבראה'!$B47)*'תכנון הבראה'!$C47,0)*(CZ$17<='תכנון הבראה'!$D47) -> 0
A20: ='תכנון הבראה'!A48 | B20: ='תכנון הבראה'!H48 -> 0 | C20: =IF(ISERROR(VLOOKUP(B20,LoanOptions,2,0)),0,VLOOKUP(B20,LoanOptions,2,0)) -> 0 | E20: =IF($A20="",0,($C20=0)*'פריסת חובות'!E11 +($C20=1)*0+ ($C20=2)*IF(E$17<='תכנון הבראה'!$K48,0,OFFSET('פריסת חובות'!E11,0,-'תכנון הבראה'!$K48))*(1+'תכנון הבראה'!$E48)^('תכנון הבראה'!$K48/12)+ ($C20=3)*'תכנון הבראה'!$L48*(E$17<='תכנון הבראה'!$J48))+ IF($C20=4,(1-'תכנון הבראה'!$M48/'תכנון הבראה'!$B48)*'תכנון הבראה'!$C48,0)*(E$17<='תכנון הבראה'!$D48) -> 0 | F20: =IF($A20="",0,($C20=0)*'פריסת חובות'!F11 +($C20=1)*0+ ($C20=2)*IF(F$17<='תכנון הבראה'!$K48,0,OFFSET('פריסת חובות'!F11,0,-'תכנון הבראה'!$K48))*(1+'תכנון הבראה'!$E48)^('תכנון הבראה'!$K48/12)+ ($C20=3)*'תכנון הבראה'!$L48*(F$17<='תכנון הבראה'!$J48))+ IF($C20=4,(1-'תכנון הבראה'!$M48/'תכנון הבראה'!$B48)*'תכנון הבראה'!$C48,0)*(F$17<='תכנון הבראה'!$D48) -> 0 | G20: =IF($A20="",0,($C20=0)*'פריסת חובות'!G11 +($C20=1)*0+ ($C20=2)*IF(G$17<='תכנון הבראה'!$K48,0,OFFSET('פריסת חובות'!G11,0,-'תכנון הבראה'!$K48))*(1+'תכנון הבראה'!$E48)^('תכנון הבראה'!$K48/12)+ ($C20=3)*'תכנון הבראה'!$L48*(G$17<='תכנון הבראה'!$J48))+ IF($C20=4,(1-'תכנון הבראה'!$M48/'תכנון הבראה'!$B48)*'תכנון הבראה'!$C48,0)*(G$17<='תכנון הבראה'!$D48) -> 0 | H20: =IF($A20="",0,($C20=0)*'פריסת חובות'!H11 +($C20=1)*0+ ($C20=2)*IF(H$17<='תכנון הבראה'!$K48,0,OFFSET('פריסת חובות'!H11,0,-'תכנון הבראה'!$K48))*(1+'תכנון הבראה'!$E48)^('תכנון הבראה'!$K48/12)+ ($C20=3)*'תכנון הבראה'!$L48*(H$17<='תכנון הבראה'!$J48))+ IF($C20=4,(1-'תכנון הבראה'!$M48/'תכנון הבראה'!$B48)*'תכנון הבראה'!$C48,0)*(H$17<='תכנון הבראה'!$D48) -> 0 | I20: =IF($A20="",0,($C20=0)*'פריסת חובות'!I11 +($C20=1)*0+ ($C20=2)*IF(I$17<='תכנון הבראה'!$K48,0,OFFSET('פריסת חובות'!I11,0,-'תכנון הבראה'!$K48))*(1+'תכנון הבראה'!$E48)^('תכנון הבראה'!$K48/12)+ ($C20=3)*'תכנון הבראה'!$L48*(I$17<='תכנון הבראה'!$J48))+ IF($C20=4,(1-'תכנון הבראה'!$M48/'תכנון הבראה'!$B48)*'תכנון הבראה'!$C48,0)*(I$17<='תכנון הבראה'!$D48) -> 0 | J20: =IF($A20="",0,($C20=0)*'פריסת חובות'!J11 +($C20=1)*0+ ($C20=2)*IF(J$17<='תכנון הבראה'!$K48,0,OFFSET('פריסת חובות'!J11,0,-'תכנון הבראה'!$K48))*(1+'תכנון הבראה'!$E48)^('תכנון הבראה'!$K48/12)+ ($C20=3)*'תכנון הבראה'!$L48*(J$17<='תכנון הבראה'!$J48))+ IF($C20=4,(1-'תכנון הבראה'!$M48/'תכנון הבראה'!$B48)*'תכנון הבראה'!$C48,0)*(J$17<='תכנון הבראה'!$D48) -> 0 | K20: =IF($A20="",0,($C20=0)*'פריסת חובות'!K11 +($C20=1)*0+ ($C20=2)*IF(K$17<='תכנון הבראה'!$K48,0,OFFSET('פריסת חובות'!K11,0,-'תכנון הבראה'!$K48))*(1+'תכנון הבראה'!$E48)^('תכנון הבראה'!$K48/12)+ ($C20=3)*'תכנון הבראה'!$L48*(K$17<='תכנון הבראה'!$J48))+ IF($C20=4,(1-'תכנון הבראה'!$M48/'תכנון הבראה'!$B48)*'תכנון הבראה'!$C48,0)*(K$17<='תכנון הבראה'!$D48) -> 0 | L20: =IF($A20="",0,($C20=0)*'פריסת חובות'!L11 +($C20=1)*0+ ($C20=2)*IF(L$17<='תכנון הבראה'!$K48,0,OFFSET('פריסת חובות'!L11,0,-'תכנון הבראה'!$K48))*(1+'תכנון הבראה'!$E48)^('תכנון הבראה'!$K48/12)+ ($C20=3)*'תכנון הבראה'!$L48*(L$17<='תכנון הבראה'!$J48))+ IF($C20=4,(1-'תכנון הבראה'!$M48/'תכנון הבראה'!$B48)*'תכנון הבראה'!$C48,0)*(L$17<='תכנון הבראה'!$D48) -> 0 | ... CZ20: =IF($A20="",0,($C20=0)*'פריסת חובות'!CZ11 +($C20=1)*0+ ($C20=2)*IF(CZ$17<='תכנון הבראה'!$K48,0,OFFSET('פריסת חובות'!CZ11,0,-'תכנון הבראה'!$K48))*(1+'תכנון הבראה'!$E48)^('תכנון הבראה'!$K48/12)+ ($C20=3)*'תכנון הבראה'!$L48*(CZ$17<='תכנון הבראה'!$J48))+ IF($C20=4,(1-'תכנון הבראה'!$M48/'תכנון הבראה'!$B48)*'תכנון הבראה'!$C48,0)*(CZ$17<='תכנון הבראה'!$D48) -> 0
